Workbook

Sheet Sprint
B6: Sprint Backlog · Sprint 3
B7: Recursos y recurrencia · del 30-09-2026 al 13-10-2026
B8: SIGMA — Sistema Integrado de Gestión de Mantenimiento Industrial · Equipo Código Creativo
B10: Objetivo del Sprint
B11: Que el sistema sepa qué repuestos hay y quién puede ejecutar el trabajo, que el trabajo planificado se genere solo por calendario o por horas de uso, y que la aplicación móvil opere sin conexión.
B15: Ficha del Sprint
B16: Sprint | C16: Sprint 3 de 6
B17: Foco | C17: Recursos y recurrencia
B18: Fechas | C18: Del 30-09-2026 al 13-10-2026 (dos semanas)
B19: Contenido | C19: Repuestos e inventario, terceros y procedimientos, motor de programación.
B20: Product Owner | C20: Catalina Pescio
B21: Scrum Master | C21: Emilio Fuentes
B22: Developer | C22: Bryan Chávez
B23: Origen de las historias | C23: SIGMA_Product_Backlog.docx · Product Backlog priorizado
B25: Capacidad y compromiso
B26: Integrantes del equipo | C26: 3
B27: Horas por integrante y por semana | C27: 40
B28: Semanas del Sprint | C28: 2
B29: Capacidad del Sprint (horas) | C29: =$C$26*$C$27*$C$28
B30: Historias comprometidas | C30: =COUNTA(Historias!$A$6:$A$34)
B31: Puntos de historia comprometidos | C31: =SUM(Historias!$H$6:$H$34)
B32: Horas planificadas en tareas | C32: =SUM(Tareas!$F$6:$F$335)
B33: Uso de la capacidad | C33: =IFERROR($C$32/$C$29,0)
B34: Holgura (horas) | C34: =$C$29-$C$32
B36: Épicas que se entregan en este Sprint
B37: Épica | C37: Nombre de la épica | D37: Historias | E37: Puntos
B38: EP-06 | C38: Repuestos, bodegas e inventario | D38: =COUNTIF(Historias!$B$6:$B$34,$B38) | E38: =SUMIF(Historias!$B$6:$B$34,$B38,Historias!$H$6:$H$34)
B39: EP-07 | C39: Terceros, procedimientos y permisos de trabajo | D39: =COUNTIF(Historias!$B$6:$B$34,$B39) | E39: =SUMIF(Historias!$B$6:$B$34,$B39,Historias!$H$6:$H$34)
B40: EP-08 | C40: Motor de programación | D40: =COUNTIF(Historias!$B$6:$B$34,$B40) | E40: =SUMIF(Historias!$B$6:$B$34,$B40,Historias!$H$6:$H$34)
B41: EP-15 | C41: Aplicación móvil y trabajo sin conexión | D41: =COUNTIF(Historias!$B$6:$B$34,$B41) | E41: =SUMIF(Historias!$B$6:$B$34,$B41,Historias!$H$6:$H$34)
B43: Celdas en amarillo con texto azul: parámetros que el equipo ajusta en el Sprint Planning. El resto se calcula solo. Las historias y su estimación provienen del Product Backlog priorizado; las tareas técnicas son la descomposición del Developer y se refinan en la planificación del Sprint.

Sheet Historias
A1: Sprint 3 · Historias comprometidas
A2: Recursos y recurrencia · del 30-09-2026 al 13-10-2026 · orden por valor de negocio
A5: ID | B5: Épica | C5: Historia de usuario | D5: Como | E5: Quiero | F5: Para | G5: Plataforma | H5: Pts | I5: Valor | J5: Prioridad | K5: Dependencias | L5: Escenarios | M5: Horas plan. | N5: Estado | O5: Responsable | P5: Observaciones
A6: HU-151 | B6: EP-15 | C6: Trabajar sin conexión | D6: técnico de mantenimiento | E6: usar la aplicación completa aunque no tenga señal | F6: no interrumpir el trabajo por una condición que la planta no puede resolver | G6: App | H6: 13 | I6: 100 | J6: Alta | K6: HU-150 | L6: 3 | M6: =SUMIF(Tareas!$B$6:$B$341,$A6,Tareas!$F$6:$F$341) | N6: Movida a Sprint 6 | O6: Bryan Chávez | P6: Movida al Sprint 6 (Sprint Review 1, 15-09-2026). Estado al moverla: Por hacer. Lado servidor listo el 16-09-2026: compuerta 402 (SuscripcionHandler) y descarga por sabana. Lo movil (T-3009/T-3011) es el MVP de la app que trabaja Bryan y no se marca todavia.
A7: HU-073 | B7: EP-08 | C7: Crear una programación por medidor | D7: planificador | E7: programar un trabajo cada cierta cantidad de horas o ciclos | F7: que el mantenimiento se dispare por uso real y no por calendario | G7: Web | H7: 8 | I7: 95 | J7: Alta | K7: HU-042 | L7: 3 | M7: =SUMIF(Tareas!$B$6:$B$341,$A7,Tareas!$F$6:$F$341) | N7: Terminada | O7: Bryan Chávez | P7: Tomada por Bryan el 17-09-2026: disparo por lectura/medición construido (bloque 243) y los 3 criterios OK con evidencia. Pruebas S3 (17-09): #3 OK (medidor por equipo). #1/#2 NO: el disparo por lectura no está construido (pendiente §10.9). DECISIÓN TOMADA 12-09-2026 (Bryan): pme_activo_medidor pasa a NULL (BD/224). Con NULL, el medidor lo aporta cada equipo del plan (Plan_Mantenimiento_Activo.pac_activo_medidor, HU-083). Una programación, cuatro blowers. Falta el disparo por lectura (generador por medidor). || Cerrada el 22-09-2026: 3/3 criterios web verificados con evidencia (SIGMA_Informe_Pruebas_Sprint_3.docx).
A8: HU-076 | B8: EP-08 | C8: Generar las ocurrencias de forma automática | D8: planificador | E8: que el sistema genere solo las ocurrencias futuras | F8: no tener que crear a mano cada mantención del año | G8: Servidor | H8: 8 | I8: 95 | J8: Alta | K8: HU-071, HU-073 | L8: 4 | M8: =SUMIF(Tareas!$B$6:$B$341,$A8,Tareas!$F$6:$F$341) | N8: Terminada | O8: Bryan Chávez | P8: Desbloqueada el 12-09-2026 al existir hitos (HU-081). Generador hecho por Bryan (BD/222); falta el job nocturno que lo dispare con @SOLO_AUTOMATICAS=1. || Cerrada el 22-09-2026: 4/4 criterios web verificados con evidencia (SIGMA_Informe_Pruebas_Sprint_3.docx).
A9: HU-071 | B9: EP-08 | C9: Crear una programación de calendario | D9: planificador | E9: programar un trabajo que se repite según el calendario | F9: cubrir rutinas diarias, semanales, mensuales y anuales | G9: Web | H9: 8 | I9: 90 | J9: Alta | K9: Sin dependencias | L9: 3 | M9: =SUMIF(Tareas!$B$6:$B$341,$A9,Tareas!$F$6:$F$341) | N9: Terminada | O9: Bryan Chávez | P9: Pruebas S3 (17-09): 3 criterios OK (martes/jueves, último día del mes con bisiesto, último viernes). Base de datos y web terminadas. El último día del mes y el último viernes salen correctos, incluido febrero bisiesto. || Cerrada el 22-09-2026: 3/3 criterios web verificados con evidencia (SIGMA_Informe_Pruebas_Sprint_3.docx).
A10: HU-053 | B10: EP-06 | C10: Definir el stock mínimo y máximo de un repuesto | D10: bodeguero | E10: establecer los umbrales de existencia de cada repuesto por bodega | F10: que el sistema avise antes de quedarme sin una pieza crítica | G10: Web | H10: 3 | I10: 85 | J10: Alta | K10: HU-052 | L10: 3 | M10: =SUMIF(Tareas!$B$6:$B$341,$A10,Tareas!$F$6:$F$341) | N10: Terminada | O10: Bryan Chávez | P10: Construida el 31-08-2026: UPS_REPUESTO_BODEGA_STOCK con las tres validaciones del CA1, editable desde la ficha del repuesto. Las alertas se ven en Existencias.aspx. Datos de prueba sembrados el 31-08 (bloque 64). FALTA la verificacion de los criterios, que es de Catalina. || Cerrada el 22-09-2026: 3/3 criterios web verificados con evidencia (SIGMA_Informe_Pruebas_Sprint_3.docx).
A11: HU-055 | B11: EP-06 | C11: Entregar repuestos contra una orden de trabajo | D11: bodeguero | E11: entregar repuestos asociándolos a la orden que los consume | F11: saber cuánto costo de repuestos tuvo cada intervención | G11: Web y App | H11: 5 | I11: 85 | J11: Alta | K11: HU-054 | L11: 3 | M11: =SUMIF(Tareas!$B$6:$B$341,$A11,Tareas!$F$6:$F$341) | N11: Terminada | O11: Bryan Chávez | P11: Construida el 31-08-2026: tipos 2 y 3 del mismo SP. El rechazo por saldo dice la existencia actual, y la devolucion reduce lo consumido de la orden. Datos de prueba sembrados el 31-08 (bloque 64). FALTA la verificacion de los criterios, que es de Catalina. || Cerrada el 22-09-2026: 3/3 criterios web verificados con evidencia (SIGMA_Informe_Pruebas_Sprint_3.docx). La parte móvil se entrega en el Sprint 6.
A12: HU-050 | B12: EP-06 | C12: Administrar el maestro de repuestos | D12: bodeguero | E12: mantener el catálogo de repuestos de la planta | F12: que todos nombren la misma pieza de la misma forma | G12: Web | H12: 5 | I12: 80 | J12: Media | K12: Sin dependencias | L12: 2 | M12: =SUMIF(Tareas!$B$6:$B$341,$A12,Tareas!$F$6:$F$341) | N12: Terminada | O12: Bryan Chávez | P12: Construida el 31-08-2026: SEL/INS/UPD/DEL_REPUESTO (bloque 60), Repuestos.aspx y Repuesto.aspx, GET /repuestos en la API. Nace rep_controla_lote, que faltaba en el modelo. Datos de prueba sembrados el 31-08 (bloque 64). FALTA la verificacion de los criterios, que es de Catalina. || Cerrada el 22-09-2026: 2/2 criterios web verificados con evidencia (SIGMA_Informe_Pruebas_Sprint_3.docx).
A13: HU-056 | B13: EP-06 | C13: Consultar la existencia de un repuesto | D13: usuario de mantenimiento | E13: saber cuántas unidades hay y dónde están | F13: no detener un trabajo por ir a buscar una pieza que no está | G13: Web y App | H13: 3 | I13: 80 | J13: Media | K13: HU-054 | L13: 2 | M13: =SUMIF(Tareas!$B$6:$B$341,$A13,Tareas!$F$6:$F$341) | N13: Terminada | O13: Bryan Chávez | P13: Construida el 31-08-2026: SEL_INVENTARIO_SALDO, Existencias.aspx y su ficha, GET /existencias. Sin cache, a proposito. Datos de prueba sembrados el 31-08 (bloque 64). FALTA la verificacion de los criterios, que es de Catalina. || Cerrada el 22-09-2026: 2/2 criterios web verificados con evidencia (SIGMA_Informe_Pruebas_Sprint_3.docx). La parte móvil se entrega en el Sprint 6.
A14: HU-075 | B14: EP-08 | C14: Definir tolerancias y exclusiones de una programación | D14: planificador | E14: indicar cuánto se puede adelantar o atrasar un trabajo y que días no aplica | F14: que el indicador de cumplimiento refleje la realidad de la planta | G14: Web | H14: 5 | I14: 80 | J14: Media | K14: Sin dependencias | L14: 3 | M14: =SUMIF(Tareas!$B$6:$B$341,$A14,Tareas!$F$6:$F$341) | N14: Terminada | O14: Bryan Chávez | P14: Pruebas S3 (17-09): 3 criterios OK (ventana, feriado desplazado con fecha original, parada de planta). Base de datos y web terminadas. Hizo falta agregar pxc_desplaza para separar la parada de planta (no genera) del feriado (corre la fecha y guarda la original). || Cerrada el 22-09-2026: 3/3 criterios web verificados con evidencia (SIGMA_Informe_Pruebas_Sprint_3.docx).
A15: HU-054 | B15: EP-06 | C15: Registrar el ingreso de repuestos a bodega | D15: bodeguero | E15: registrar la recepción de repuestos con su lote y documento | F15: que la existencia del sistema coincida con la de la estantería | G15: Web y App | H15: 5 | I15: 75 | J15: Media | K15: HU-052 | L15: 2 | M15: =SUMIF(Tareas!$B$6:$B$341,$A15,Tareas!$F$6:$F$341) | N15: Terminada | O15: Bryan Chávez | P15: Construida el 31-08-2026: INS_INVENTARIO_MOVIMIENTO tipo 1, que exige el lote cuando el repuesto lo controla. POST /inventario-movimientos idempotente por uuid. Datos de prueba sembrados el 31-08 (bloque 64). FALTA la verificacion de los criterios, que es de Catalina. || Cerrada el 22-09-2026: 2/2 criterios web verificados con evidencia (SIGMA_Informe_Pruebas_Sprint_3.docx). La parte móvil se entrega en el Sprint 6.
A16: HU-060 | B16: EP-07 | C16: Administrar proveedores | D16: jefe de mantenimiento | E16: mantener el registro de las empresas que prestan servicios | F16: poder sumar al cierre del año cuánto se gastó en cada contratista | G16: Web | H16: 5 | I16: 75 | J16: Media | K16: Sin dependencias | L16: 2 | M16: =SUMIF(Tareas!$B$6:$B$341,$A16,Tareas!$F$6:$F$341) | N16: Terminada | O16: Bryan Chávez | P16: Construida por Bryan (bloque 91). Pruebas S3 (17-09): 2 criterios OK. || Cerrada el 22-09-2026: 2/2 criterios web verificados con evidencia (SIGMA_Informe_Pruebas_Sprint_3.docx).
A17: HU-051 | B17: EP-06 | C17: Definir la compatibilidad de un repuesto | D17: planificador | E17: indicar en qué equipos o modelos aplica cada repuesto | F17: que el técnico no monte una pieza que no corresponde | G17: Web | H17: 3 | I17: 70 | J17: Media | K17: HU-050 | L17: 2 | M17: =SUMIF(Tareas!$B$6:$B$341,$A17,Tareas!$F$6:$F$341) | N17: Terminada | O17: Bryan Chávez | P17: Construida por Bryan (bloque 92). Pruebas S3 (17-09): #1 OK; #2 OK con la regla nueva del bloque 242 (consumo contra OT de un equipo no compatible exige el motivo). || Cerrada el 22-09-2026: 2/2 criterios web verificados con evidencia (SIGMA_Informe_Pruebas_Sprint_3.docx).
... A34: HU-077 | B34: EP-06 | C34: Que el sistema avise lo que encuentra | D34: jefe de mantenimiento | E34: que el sistema detecte solo los problemas de operación y me los notifique | F34: enterarme de un quiebre de stock cuando ocurre y no cuando alguien lo reporta | G34: Web y App | H34: 8 | I34: 95 | J34: Alta | K34: HU-053 | L34: 4 | M34: =SUMIF(Tareas!$B$6:$B$341,$A34,Tareas!$F$6:$F$341) | N34: Terminada | O34: Bryan Chávez | P34: Detectores de los otros modulos listos el 16-09-2026 (bloque 238): quedan las pruebas y documentacion de Catalina (T-3958/T-3959). || Cerrada el 22-09-2026: 4/4 criterios web verificados con evidencia (SIGMA_Informe_Pruebas_Sprint_3.docx). La parte móvil se entrega en el Sprint 6.
C35: Total del Sprint | H35: =SUM(H6:H34) | L35: =SUM(L6:L34) | M35: =SUM(M6:M34)

Sheet Tareas
A1: Sprint 3 · Tareas del Sprint
A2: Descomposición técnica de cada historia comprometida. Se refina en el Sprint Planning y se actualiza en el Daily Scrum.
A5: Tarea | B5: Historia | C5: Título de la historia | D5: Tarea técnica | E5: Tipo | F5: Horas est. | G5: Responsable | H5: Estado | I5: Horas reales | J5: Observaciones
A6: T-3001 | B6: HU-151 | C6: Trabajar sin conexión | D6: Modelo: CREAR la tabla Sincronizacion_Lote — todavía no existe. Columnas, PK, FK a sus padres y columna sin_uuid con índice UNIQUE para que la sincronización no duplique. | E6: Base de datos | F6: 1.5 | G6: Bryan Chávez | H6: Movida a Sprint 6 | J6: Movida al Sprint 6 (Sprint Review 1, 15-09-2026). Estado al moverla: Descartada. Misma decision que en HU-150: la subida es por recurso con uuid (patron 209), no hay lote que persistir. Sincronizacion_Lote no se crea.
A7: T-3002 | B7: HU-151 | C7: Trabajar sin conexión | D7: SP SEL_SINCRONIZACION: lo que baja al teléfono, acotado al usuario y a su planta. | E7: Base de datos | F7: 1.25 | G7: Emilio Fuentes | H7: Movida a Sprint 6 | J7: Movida al Sprint 6 (Sprint Review 1, 15-09-2026). Estado al moverla: Por hacer.
A8: T-3003 | B8: HU-151 | C8: Trabajar sin conexión | D8: SP INS_SINCRONIZACION: recepción de lo que sube el teléfono, idempotente por uuid: el reenvío choca contra el índice en vez de duplicar. | E8: Base de datos | F8: 1.25 | G8: Catalina Pescio | H8: Movida a Sprint 6 | J8: Movida al Sprint 6 (Sprint Review 1, 15-09-2026). Estado al moverla: Por hacer.
A9: T-3004 | B9: HU-151 | C9: Trabajar sin conexión | D9: Datos de prueba en Sincronizacion_Lote para poder ejercitar los criterios de aceptación. | E9: Base de datos | F9: 1.25 | G9: Bryan Chávez | H9: Movida a Sprint 6 | J9: Movida al Sprint 6 (Sprint Review 1, 15-09-2026). Estado al moverla: Descartada. Sin tabla de lotes no hay datos que sembrar.
A10: T-3005 | B10: HU-151 | C10: Trabajar sin conexión | D10: GET /api/sincronizaciones/sync — descarga para el dispositivo, filtrada por usuario y planta. | E10: API | F10: 1.5 | G10: Bryan Chávez | H10: Movida a Sprint 6 | I10: 1.5 | J10: Movida al Sprint 6 (Sprint Review 1, 15-09-2026). Estado al moverla: Terminada. Ya existia como la sabana: GET /sincronizacion (manifiesto) y GET /sincronizacion/{bloque}?desde=, acotada a las plantas del usuario por API_SEL_APP_SABANA_DATOS (bloques 140-234).
A11: T-3006 | B11: HU-151 | C11: Trabajar sin conexión | D11: POST /api/sincronizaciones/sync — subida por lotes, idempotente por uuid. | E11: API | F11: 1.25 | G11: Emilio Fuentes | H11: Movida a Sprint 6 | J11: Movida al Sprint 6 (Sprint Review 1, 15-09-2026). Estado al moverla: Por hacer.
A12: T-3007 | B12: HU-151 | C12: Trabajar sin conexión | D12: Middleware: validar la KEY del cliente contra FNC_SUSCRIPCION_VIGENTE y responder 402 si la suscripción no permite operar. | E12: API | F12: 1.25 | G12: Bryan Chávez | H12: Movida a Sprint 6 | I12: 1.25 | J12: Movida al Sprint 6 (Sprint Review 1, 15-09-2026). Estado al moverla: Terminada. SuscripcionHandler en el pipeline de Web API: con cliente en el token y PUEDE_OPERAR=0 (SEL_SUSCRIPCION_ESTADO_CLIENTE -> FNC_SUSCRIPCION_VIGENTE) responde 402 con el cuerpo estandar; cache 60 s por cliente; registra en Suscripcion_Bloqueo_Log origen API; exentas /sesion, /cliente-usuarios, /mi-perfil.
A13: T-3009 | B13: HU-151 | C13: Trabajar sin conexión | D13: Pantalla Flutter de trabajo sin conexión, usable con guantes: objetivos grandes y sin gestos finos. | E13: Móvil | F13: 0.75 | G13: Bryan Chávez | H13: Movida a Sprint 6 | J13: Movida al Sprint 6 (Sprint Review 1, 15-09-2026). Estado al moverla: Por hacer.
A14: T-3010 | B14: HU-151 | C14: Trabajar sin conexión | D14: Guardar en SQLite local primero y encolar el envío: en terreno no hay señal y el trabajo no se puede perder. | E14: Móvil | F14: 0.75 | G14: Emilio Fuentes | H14: Movida a Sprint 6 | J14: Movida al Sprint 6 (Sprint Review 1, 15-09-2026). Estado al moverla: Por hacer.
A15: T-3011 | B15: HU-151 | C15: Trabajar sin conexión | D15: Reintento de la cola con corte de red a medias, sin duplicar. | E15: Móvil | F15: 0.75 | G15: Bryan Chávez | H15: Movida a Sprint 6 | J15: Movida al Sprint 6 (Sprint Review 1, 15-09-2026). Estado al moverla: Por hacer.
A16: T-3012 | B16: HU-151 | C16: Trabajar sin conexión | D16: Permiso en el servidor: la acción se valida con Token.Puede / ExigirPagina, no escondiendo el botón. Y filtrar por cliente en sesión para que no se vea lo de otra empresa. | E16: Seguridad | F16: 1.5 | G16: Bryan Chávez | H16: Movida a Sprint 6 | I16: 1.5 | J16: Movida al Sprint 6 (Sprint Review 1, 15-09-2026). Estado al moverla: Terminada. La API valida permiso con ExigirPermiso/ExigirCliente y el cliente sale del token, nunca de un parametro; la sabana filtra por las plantas del usuario.
A17: T-3013 | B17: HU-151 | C17: Trabajar sin conexión | D17: Escribir y ejecutar un caso de prueba por cada criterio de aceptación de la historia, y dejar el resultado en la hoja Criterios de aceptación. | E17: Pruebas | F17: 1.75 | G17: Catalina Pescio | H17: Movida a Sprint 6 | J17: Movida al Sprint 6 (Sprint Review 1, 15-09-2026). Estado al moverla: Por hacer.
A18: T-3014 | B18: HU-151 | C18: Trabajar sin conexión | D18: Documentar el endpoint en Swagger y anotar en el MD de estado las decisiones que un tercero no podría deducir del código. | E18: Documentación | F18: 0.75 | G18: Catalina Pescio | H18: Movida a Sprint 6 | J18: Movida al Sprint 6 (Sprint Review 1, 15-09-2026). Estado al moverla: Por hacer.
A19: T-3015 | B19: HU-151 | C19: Trabajar sin conexión | D19: Validación funcional con la Product Owner sobre la pantalla terminada. | E19: Validación | F19: 0.5 | G19: Catalina Pescio | H19: Movida a Sprint 6 | J19: Movida al Sprint 6 (Sprint Review 1, 15-09-2026). Estado al moverla: Por hacer.
A20: T-3016 | B20: HU-073 | C20: Crear una programación por medidor | D20: Modelo: revisar Programacion — columnas, FK e índices. Confirmar el índice único del código dentro del cliente. | E20: Base de datos | F20: 0.75 | G20: Emilio Fuentes | H20: Terminada | J20: Modelo revisado. DECISION PENDIENTE: pme_activo_medidor es NOT NULL y el criterio 3 (un plan, cuatro blowers) necesita que sea nullable.
A21: T-3017 | B21: HU-073 | C21: Crear una programación por medidor | D21: SP INS_PROGRAMACION_MEDIDOR: alta transaccional con las validaciones de negocio de la historia. Devuelve el id creado por OUTPUT. | E21: Base de datos | F21: 0.75 | G21: Bryan Chávez | H21: Terminada | J21: Implementado como UPS_ (upsert) y no como INS_/UPD_ separados: el detalle es 1..1 con la programacion, y separarlos obliga a la pantalla a preguntar antes cual llamar.
A22: T-3018 | B22: HU-073 | C22: Crear una programación por medidor | D22: SP SEL_PROGRAMACION_MEDIDOR: consulta por id y por filtros, para la ficha y el listado. | E22: Base de datos | F22: 0.75 | G22: Bryan Chávez | H22: Terminada | J22: Bloque 104. Calcula ademas el proximo valor de disparo.
A23: T-3019 | B23: HU-073 | C23: Crear una programación por medidor | D23: SP UPD_PROGRAMACION_MEDIDOR: corrección del registro mientras esté en un estado que lo permita. | E23: Base de datos | F23: 0.75 | G23: Bryan Chávez | H23: Terminada | J23: Implementado como UPS_ (upsert) y no como INS_/UPD_ separados: el detalle es 1..1 con la programacion, y separarlos obliga a la pantalla a preguntar antes cual llamar.
A24: T-3020 | B24: HU-073 | C24: Crear una programación por medidor | D24: Datos de prueba en Programacion para poder ejercitar los criterios de aceptación. | E24: Base de datos | F24: 0.75 | G24: Bryan Chávez | H24: Terminada | I24: 0.75 | J24: La decisión del criterio 3 (pme_activo_medidor NULL, BD/224) permite una programación por medidor sin horómetro fijo; el medidor lo pone cada equipo del plan (pac_activo_medidor).
A25: T-3024 | B25: HU-073 | C25: Crear una programación por medidor | D25: Ficha ProgramacionMedidor.aspx: formulario de alta con sus validaciones. | E25: Web | F25: 1.25 | G25: Bryan Chávez | H25: Descartada | J25: Descartada por diseno: se resolvio con UNA ficha y UN listado (T-3239 / T-3240). Programacion es una cabecera con cinco variantes de detalle, no cinco entidades; cinco pantallas serian las mismas secciones comunes copiadas cinco veces.
A26: T-3025 | B26: HU-073 | C26: Crear una programación por medidor | D26: Listado ProgramacionMedidors.aspx con el estado de cada registro. | E26: Web | F26: 1.25 | G26: Bryan Chávez | H26: Descartada | J26: Descartada por diseno: se resolvio con UNA ficha y UN listado (T-3239 / T-3240). Programacion es una cabecera con cinco variantes de detalle, no cinco entidades; cinco pantallas serian las mismas secciones comunes copiadas cinco veces.
A27: T-3026 | B27: HU-073 | C27: Crear una programación por medidor | D27: Permiso en el servidor: la acción se valida con Token.Puede / ExigirPagina, no escondiendo el botón. Y filtrar por cliente en sesión para que no se vea lo de otra empresa. | E27: Seguridad | F27: 1 | G27: Emilio Fuentes | H27: Terminada | J27: Cubierto por T-3241.
A28: T-3027 | B28: HU-073 | C28: Crear una programación por medidor | D28: Escribir y ejecutar un caso de prueba por cada criterio de aceptación de la historia, y dejar el resultado en la hoja Criterios de aceptación. | E28: Pruebas | F28: 1.25 | G28: Catalina Pescio | H28: Terminada | I28: 1.25 | J28: Ejecutadas por Bryan Chávez el 17-09-2026 con evidencia por criterio (Informe de Pruebas Sprint 3, capturas/S3).
A29: T-3028 | B29: HU-073 | C29: Crear una programación por medidor | D29: Documentar el endpoint en Swagger y anotar en el MD de estado las decisiones que un tercero no podría deducir del código. | E29: Documentación | F29: 0.5 | G29: Catalina Pescio | H29: Terminada | I29: 0.5 | J29: Swagger (comentarios XML) y MD de estado al día el 22-09-2026.
A30: T-3029 | B30: HU-073 | C30: Crear una programación por medidor | D30: Validación funcional con la Product Owner sobre la pantalla terminada. | E30: Validación | F30: 0.25 | G30: Catalina Pescio | H30: Terminada | I30: 0.25 | J30: Validado con la Product Owner (registrado el 27-09-2026 por indicación de Bryan Chávez).
A31: T-3030 | B31: HU-076 | C31: Generar las ocurrencias de forma automática | D31: Modelo: revisar Plan_Mantenimiento_Ocurrencia — columnas, FK e índices. Confirmar el índice único del código dentro del cliente. | E31: Base de datos | F31: 1 | G31: Bryan Chávez | H31: Terminada | J31: Revisado. HALLAZGO: pmo_plan_mantenimiento_hito es NOT NULL contra Plan_Mantenimiento_Hito, que es HU-081 del Sprint 4 y esta vacia. Por eso hoy no se puede insertar ninguna ocurrencia.
A32: T-3031 | B32: HU-076 | C32: Generar las ocurrencias de forma automática | D32: SP PLAN_OCURRENCIA: el proceso completo dentro de una transacción, con SET XACT_ABORT ON para que un error no deje datos a medias. | E32: Base de datos | F32: 0.75 | G32: Bryan Chávez | H32: Terminada | I32: 0.75 | J32: BD/222 GEN_PLAN_OCURRENCIAS y GEN_TAREA_OCURRENCIAS: XACT_ABORT, idempotentes, con Programacion_Generacion como marca de agua.
A33: T-3032 | B33: HU-076 | C33: Generar las ocurrencias de forma automática | D33: Reglas de negocio de la historia en el SP, no en la pantalla: la API y la web tienen que obtener el mismo resultado. | E33: Base de datos | F33: 0.75 | G33: Bryan Chávez | H33: Terminada | I33: 0.75 | J33: Reglas en el SP: solo versiones publicadas, programaciones habilitadas, sin duplicar por los dos índices únicos.
A34: T-3033 | B34: HU-076 | C34: Generar las ocurrencias de forma automática | D34: SP SEL_PLAN_OCURRENCIA: consultar el resultado del proceso. | E34: Base de datos | F34: 0.75 | G34: Bryan Chávez | H34: Terminada | I34: 0.75 | J34: SEL_PLAN_CALENDARIO (BD/216) devuelve el resultado; el SP de generación devuelve el resumen por plan e hito.
A35: T-3034 | B35: HU-076 | C35: Generar las ocurrencias de forma automática | D35: Datos de prueba en Plan_Mantenimiento_Ocurrencia para poder ejercitar los criterios de aceptación. | E35: Base de datos | F35: 0.75 | G35: Bryan Chávez | H35: Terminada | I35: 0.75 | J35: _SEMILLA_PLAN_CALENDARIO.sql + generación real sobre PMA-HORNOS-L1.
A36: T-3035 | B36: HU-076 | C36: Generar las ocurrencias de forma automática | D36: POST /api/plan-ocurrencias — dispara el proceso y devuelve su resultado. | E36: API | F36: 1.5 | G36: Bryan Chávez | H36: Terminada | I36: 1.5 | J36: POST /plan-ocurrencias/generar (PlanOcurrenciasController). Probado por HTTP.
A37: T-3036 | B37: HU-076 | C37: Generar las ocurrencias de forma automática | D37: Manejo de errores del SP: cada RAISERROR se traduce a un código HTTP con mensaje, no a un 500 genérico. | E37: API | F37: 1.25 | G37: Bryan Chávez | H37: Terminada | I37: 1.25 | J37: Los RAISERROR llegan como 400 esDeNegocio (plan sin versión publicada verificado).
A38: T-3037 | B38: HU-076 | C38: Generar las ocurrencias de forma automática | D38: Pantalla PlanOcurrencia.aspx: disparar el proceso, mostrar el resultado y dejar constancia de quién lo ejecutó. | E38: Web | F38: 2.25 | G38: Bryan Chávez | H38: Terminada | I38: 2.25 | J38: Sin pantalla suelta: botón «Generar ocurrencias» en la pestaña Calendario del plan y en la tarea, con resultado y usuario.
A39: T-3038 | B39: HU-076 | C39: Generar las ocurrencias de forma automática | D39: Permiso en el servidor: la acción se valida con Token.Puede / ExigirPagina, no escondiendo el botón. Y filtrar por cliente en sesión para que no se vea lo de otra empresa. | E39: Seguridad | F39: 1 | G39: Bryan Chávez | H39: Terminada | I39: 1 | J39: CREAR EDITAR PLANES MANTENIMIENTO en web y API; técnico -> 403 verificado.
A40: T-3039 | B40: HU-076 | C40: Generar las ocurrencias de forma automática | D40: Escribir y ejecutar un caso de prueba por cada criterio de aceptación de la historia, y dejar el resultado en la hoja Criterios de aceptación. | E40: Pruebas | F40: 1.25 | G40: Bryan Chávez | H40: Terminada | I40: 1.25 | J40: Ejecutados por Bryan (ver S4 y MD): horizonte, repetida sin duplicar, manual, programación deshabilitada.
A41: T-3040 | B41: HU-076 | C41: Generar las ocurrencias de forma automática | D41: Documentar el endpoint en Swagger y anotar en el MD de estado las decisiones que un tercero no podría deducir del código. | E41: Documentación | F41: 0.5 | G41: Bryan Chávez | H41: Terminada | I41: 0.5 | J41: XML del controlador + MD.
A42: T-3041 | B42: HU-076 | C42: Generar las ocurrencias de forma automática | D42: Validación funcional con la Product Owner sobre la pantalla terminada. | E42: Validación | F42: 0.25 | G42: Bryan Chávez | H42: Terminada | I42: 0.25 | J42: Pendiente de la PO. · Validado con la Product Owner (registrado el 27-09-2026 por indicación de Bryan Chávez).
...

Sheet Criterios de aceptación
A1: Sprint 3 · Criterios de aceptación
A2: Definición contractual de terminado de cada historia. Todos deben pasar para dar la historia por hecha.
A5: Historia | B5: Título de la historia | C5: N.º | D5: Escenario | E5: Criterio (Dado / Cuando / Entonces) | F5: Verificado
A6: HU-151 | B6: Trabajar sin conexión | C6: 1 | D6: Turno completo sin señal | E6: Dado que estoy sin conexión desde que entré a la planta Cuando escaneo códigos, abro órdenes, ejecuto checklists, dicto observaciones y tomo fotografías Entonces todo funciona sin ningún mensaje de error de red | F6: Sprint 6
A7: HU-151 | B7: Trabajar sin conexión | C7: 2 | D7: Indicador permanente | E7: Cuando estoy sin conexión Entonces un indicador visible muestra el estado y la cantidad de cambios pendientes | F7: Sprint 6
A8: HU-151 | B8: Trabajar sin conexión | C8: 3 | D8: Espacio disponible | E8: Cuando el almacenamiento del dispositivo está por agotarse Entonces se advierte antes de que impida seguir capturando evidencias | F8: Sprint 6
A9: HU-073 | B9: Crear una programación por medidor | C9: 1 | D9: Disparo por horas | E9: Dado un plan cada 500 horas y un horómetro en 8.200 al cierre del hito anterior Cuando se registra una lectura de 8.700 horas Entonces se genera la ocurrencia correspondiente | F9: Sí
A10: HU-073 | B10: Crear una programación por medidor | C10: 2 | D10: Aviso anticipado | E10: Dado un plan cada 500 horas con aviso 50 horas antes Cuando se registra una lectura de 8.655 horas Entonces se genera una alerta de medidor próximo a mantenimiento Y la alerta no genera una orden de trabajo por si sola | F10: Sí
A11: HU-073 | B11: Crear una programación por medidor | C11: 3 | D11: Un horómetro por equipo | E11: Dado un plan aplicado a cuatro blowers identicos Entonces cada equipo dispara según su propio horómetro Y no se requiere crear cuatro planes | F11: Sí
A12: HU-076 | B12: Generar las ocurrencias de forma automática | C12: 1 | D12: Generación por horizonte | E12: Cuando el proceso automático se ejecuta Entonces genera las ocurrencias de los próximos 90 días Y avanza la marca de agua hasta la fecha generada | F12: Sí
A13: HU-076 | B13: Generar las ocurrencias de forma automática | C13: 2 | D13: Ejecución repetida | E13: Cuando el proceso automático se ejecuta dos veces seguidas Entonces la segunda ejecución no genera ocurrencias duplicadas | F13: Sí
A14: HU-076 | B14: Generar las ocurrencias de forma automática | C14: 3 | D14: Generación manual | E14: Cuando solicito generar ocurrencias de una programación específica Entonces se generan de inmediato sin esperar al proceso automático | F14: Sí
A15: HU-076 | B15: Generar las ocurrencias de forma automática | C15: 4 | D15: Programación deshabilitada | E15: Dado que deshabilito una programación Entonces deja de generar ocurrencias nuevas Y las ya generadas se conservan La marca de agua es lo que hace idempotente la generación. Sin ella, dos ejecuciones del proceso crean la misma ocurrencia dos veces y el técnico ve trabajo duplicado. | F15: Sí
A16: HU-071 | B16: Crear una programación de calendario | C16: 1 | D16: Recurrencia semanal | E16: Cuando defino repetición semanal los martes y jueves Entonces se generan ocurrencias en cada martes y jueves del periodo de vigencia | F16: Sí
A17: HU-071 | B17: Crear una programación de calendario | C17: 2 | D17: Último día del mes | E17: Cuando defino repetición mensual el último día del mes Entonces la ocurrencia de febrero cae el 28 o el 29 según corresponda Y la de enero cae el 31 | F17: Sí
... A81: HU-077 | B81: Que el sistema avise lo que encuentra | C81: 4 | D81: La app recibe lo mismo | E81: Cuando la app consulta GET /alertas y /alertas/resumen Entonces recibe las mismas alertas y el mismo contador que la web | F81: Sí

Sheet Definition of Done
A1: Definition of Done
A2: Se aplica por igual a toda historia de todo Sprint. Una historia que no cumple los diez criterios no está terminada.
A4: N.º | B4: Dimensión | C4: Criterio | D4: Cumple
A5: 1 | B5: Funcionalidad | C5: Todos los criterios de aceptación de la historia se verifican y pasan. | D5: No
A6: 2 | B6: Seguridad | C6: Los permisos se validan en el servidor y no solamente ocultando controles en la interfaz. | D6: No
A7: 3 | B7: Terreno | C7: Si la historia involucra la aplicación móvil, funciona sin conexión y sincroniza sin generar registros duplicados. | D7: No
A8: 4 | B8: Multicliente | C8: Ningún dato de otro cliente resulta accesible. Se verifica de forma explícita con dos clientes cargados. | D8: No
A9: 5 | B9: Idioma | C9: Los textos están en español de Chile y no hay cadenas de texto fijas en el código. | D9: No
A10: 6 | B10: Despliegue | C10: La funcionalidad está desplegada en el ambiente de demostración con datos de prueba. | D10: No
A11: 7 | B11: Usabilidad | C11: Una persona ajena al equipo la utiliza sin explicación previa y completa la tarea. | D11: No
A12: 8 | B12: Pruebas | C12: Existe al menos un caso de prueba por escenario de aceptación y todos se ejecutan con resultado correcto antes de dar la historia por terminada. | D12: No
A13: 9 | B13: Revisión de código | C13: El código fue revisado por un integrante distinto de quien lo escribió, está integrado en la rama principal y no deja advertencias del compilador. | D13: No
A14: 10 | B14: Documentación | C14: El endpoint queda documentado en Swagger, el cambio en el modelo de datos queda registrado y la historia queda cerrada en el Sprint Backlog. | D14: No
A16: El criterio 7 es el más exigente y el más útil: una pantalla que necesita a su desarrollador al lado para ser usada no está terminada, está demostrada. El detalle completo, con la forma de verificar cada criterio y quién lo verifica, está en el documento SIGMA_Definition_of_Done.docx.
