Workbook

Sheet Resumen
B6: Product Backlog priorizado
B7: SIGMA — Sistema Integrado de Gestión de Mantenimiento Industrial
B8: Detalle por Sprint · Equipo Código Creativo · Cliente piloto: Hamburgo S.A., Planta Renca
B10: Ficha del proyecto
B11: Metodología | C11: Scrum · Sprints de dos semanas
B12: Product Owner | C12: Catalina Pescio
B13: Scrum Master | C13: Emilio Fuentes
B14: Developer | C14: Bryan Chávez
B15: Inicio de la planificación | C15: 19 de agosto de 2026
B16: Cierre del proyecto | C16: 1 de diciembre de 2026
B17: Documento de origen | C17: SIGMA_Product_Backlog.docx · versión 1.0
B19: Indicadores del backlog
B20: Épicas | C20: Historias de usuario | D20: Puntos de historia | E20: Criterios de aceptación | F20: Campos de entrada | G20: Sprints de desarrollo
B21: =COUNTA(Épicas!A6:A26) | C21: =COUNTA('Backlog completo'!A6:A155) | D21: =SUM('Backlog completo'!J6:J155) | E21: =COUNTA('Criterios de aceptación'!A6:A442) | F21: =COUNTA('Campos de entrada'!A6:A563) | G21: =6
B23: Distribución por Sprint
B24: Sprint | C24: Desde | D24: Hasta | E24: Objetivo | F24: Historias | G24: Puntos | H24: % del total | I24: Avance
B25: Sprint 1 | C25: 02-09-2026 | D25: 15-09-2026 | E25: Fundaciones | F25: =COUNTIF('Backlog completo'!$L$6:$L$155,$B25) | G25: =SUMIF('Backlog completo'!$L$6:$L$155,$B25,'Backlog completo'!$J$6:$J$155) | H25: =IFERROR($G25/SUM($G$25:$G$30),0) | I25: =IFERROR(Seguimiento!$E6/Seguimiento!$D6,0)
B26: Sprint 2 | C26: 16-09-2026 | D26: 29-09-2026 | E26: Activos | F26: =COUNTIF('Backlog completo'!$L$6:$L$155,$B26) | G26: =SUMIF('Backlog completo'!$L$6:$L$155,$B26,'Backlog completo'!$J$6:$J$155) | H26: =IFERROR($G26/SUM($G$25:$G$30),0) | I26: =IFERROR(Seguimiento!$E7/Seguimiento!$D7,0)
B27: Sprint 3 | C27: 30-09-2026 | D27: 13-10-2026 | E27: Recursos y recurrencia | F27: =COUNTIF('Backlog completo'!$L$6:$L$155,$B27) | G27: =SUMIF('Backlog completo'!$L$6:$L$155,$B27,'Backlog completo'!$J$6:$J$155) | H27: =IFERROR($G27/SUM($G$25:$G$30),0) | I27: =IFERROR(Seguimiento!$E8/Seguimiento!$D8,0)
B28: Sprint 4 | C28: 14-10-2026 | D28: 27-10-2026 | E28: Trabajo planificado | F28: =COUNTIF('Backlog completo'!$L$6:$L$155,$B28) | G28: =SUMIF('Backlog completo'!$L$6:$L$155,$B28,'Backlog completo'!$J$6:$J$155) | H28: =IFERROR($G28/SUM($G$25:$G$30),0) | I28: =IFERROR(Seguimiento!$E9/Seguimiento!$D9,0)
B29: Sprint 5 | C29: 28-10-2026 | D29: 10-11-2026 | E29: Ejecución | F29: =COUNTIF('Backlog completo'!$L$6:$L$155,$B29) | G29: =SUMIF('Backlog completo'!$L$6:$L$155,$B29,'Backlog completo'!$J$6:$J$155) | H29: =IFERROR($G29/SUM($G$25:$G$30),0) | I29: =IFERROR(Seguimiento!$E10/Seguimiento!$D10,0)
B30: Sprint 6 | C30: 11-11-2026 | D30: 24-11-2026 | E30: App móvil, inteligencia y cierre | F30: =COUNTIF('Backlog completo'!$L$6:$L$155,$B30) | G30: =SUMIF('Backlog completo'!$L$6:$L$155,$B30,'Backlog completo'!$J$6:$J$155) | H30: =IFERROR($G30/SUM($G$25:$G$30),0) | I30: =IFERROR(Seguimiento!$E11/Seguimiento!$D11,0)
B31: Total | F31: =SUM(F25:F30) | G31: =SUM(G25:G30) | H31: =SUM(H25:H30) | I31: =IFERROR(SUM(Seguimiento!$E$6:$E$11)/SUM(Seguimiento!$D$6:$D$11),0)
B33: Distribución por prioridad
B34: Prioridad | C34: Valor de negocio | D34: Historias | E34: Puntos | F34: % de los puntos
B35: Alta | C35: 85 a 100 | D35: =COUNTIF('Backlog completo'!$K$6:$K$155,$B35) | E35: =SUMIF('Backlog completo'!$K$6:$K$155,$B35,'Backlog completo'!$J$6:$J$155) | F35: =IFERROR($E35/SUM($E$35:$E$37),0)
B36: Media | C36: 65 a 84 | D36: =COUNTIF('Backlog completo'!$K$6:$K$155,$B36) | E36: =SUMIF('Backlog completo'!$K$6:$K$155,$B36,'Backlog completo'!$J$6:$J$155) | F36: =IFERROR($E36/SUM($E$35:$E$37),0)
B37: Baja | C37: menor a 65 | D37: =COUNTIF('Backlog completo'!$K$6:$K$155,$B37) | E37: =SUMIF('Backlog completo'!$K$6:$K$155,$B37,'Backlog completo'!$J$6:$J$155) | F37: =IFERROR($E37/SUM($E$35:$E$37),0)
B39: Fuente: SIGMA_Product_Backlog.docx (Fase 2). Los indicadores de esta hoja se calculan con fórmulas sobre las hojas de detalle; la columna Avance se alimenta del estado que se registre en cada hoja de Sprint.

Sheet Plan de Sprints
A1: Plan de Sprints
A2: Calendario del proyecto · Sprints de dos semanas
A4: Sprint | B4: Desde | C4: Hasta | D4: Objetivo del Sprint | E4: Contenido | F4: Historias | G4: Puntos
A5: Sprint 0 | B5: 19-08-2026 | C5: 01-09-2026 | D5: Planificación | E5: Levantamiento, modelo de datos, arquitectura, ambientes y backlog priorizado. | F5: — | G5: —
A6: Sprint 1 | B6: 02-09-2026 | C6: 15-09-2026 | D6: Fundaciones | E6: Acceso, seguridad, multicliente, estructura organizacional y catálogos. | F6: =COUNTIF('Backlog completo'!$L$6:$L$155,$A6) | G6: =SUMIF('Backlog completo'!$L$6:$L$155,$A6,'Backlog completo'!$J$6:$J$155)
A7: Sprint 2 | B7: 16-09-2026 | C7: 29-09-2026 | D7: Activos | E7: Maestro de activos, ubicación técnica y mediciones. La sincronización inicial de la app pasa al Sprint 6. | F7: =COUNTIF('Backlog completo'!$L$6:$L$155,$A7) | G7: =SUMIF('Backlog completo'!$L$6:$L$155,$A7,'Backlog completo'!$J$6:$J$155)
A8: Sprint 3 | B8: 30-09-2026 | C8: 13-10-2026 | D8: Recursos y recurrencia | E8: Repuestos e inventario, terceros y procedimientos, motor de programación. | F8: =COUNTIF('Backlog completo'!$L$6:$L$155,$A8) | G8: =SUMIF('Backlog completo'!$L$6:$L$155,$A8,'Backlog completo'!$J$6:$J$155)
A9: Sprint 4 | B9: 14-10-2026 | C9: 27-10-2026 | D9: Trabajo planificado | E9: Planes de mantenimiento, checklist dinámico y tareas. | F9: =COUNTIF('Backlog completo'!$L$6:$L$155,$A9) | G9: =SUMIF('Backlog completo'!$L$6:$L$155,$A9,'Backlog completo'!$J$6:$J$155)
A10: Sprint 5 | B10: 28-10-2026 | C10: 10-11-2026 | D10: Ejecución | E10: Órdenes de trabajo, fallas, bitácora y evidencias en la web; centro comercial, cobros y procesos automáticos; soporte; SIGMA Twin; carga de datos. | F10: =COUNTIF('Backlog completo'!$L$6:$L$155,$A10) | G10: =SUMIF('Backlog completo'!$L$6:$L$155,$A10,'Backlog completo'!$J$6:$J$155)
A11: Sprint 6 | B11: 11-11-2026 | C11: 24-11-2026 | D11: App móvil, inteligencia y cierre | E11: Aplicación móvil completa (todas las historias de plataforma App, reprogramadas en la Sprint Review 1), SIGMA AI, dashboard, suscripción e importación de datos. | F11: =COUNTIF('Backlog completo'!$L$6:$L$155,$A11) | G11: =SUMIF('Backlog completo'!$L$6:$L$155,$A11,'Backlog completo'!$J$6:$J$155)
A12: Cierre | B12: 25-11-2026 | C12: 01-12-2026 | D12: Validación | E12: Pruebas con Hamburgo S.A., corrección de observaciones y entrega final. | F12: — | G12: —
A13: Los Sprints 0 y de Cierre no contienen historias del backlog: corresponden a la planificación previa y a la validación final con el cliente. Cambio de alcance del 15-09-2026 (Sprint Review 1): el cliente pidió concentrar los Sprints 1 a 5 en la web, para que la configuración base exista antes de poner la app en manos de los técnicos; todas las historias de plataforma App se entregan en el Sprint 6.
A14: Los Sprints 0 y de Cierre no contienen historias del backlog: corresponden a la planificación previa y a la validación final con el cliente.

Sheet Épicas
A1: Resumen por épica
A2: 21 épicas · objetivo, volumen y Sprint principal
A5: ID | B5: Épica | C5: Objetivo | D5: Historias | E5: Puntos | F5: Valor medio | G5: Sprint principal | H5: % de los puntos
A6: EP-01 | B6: Acceso, seguridad y multicliente | C6: Que cada persona entre a SIGMA y vea únicamente lo que le corresponde, en el cliente que le corresponde. | D6: =COUNTIF('Backlog completo'!$B$6:$B$155,$A6) | E6: =SUMIF('Backlog completo'!$B$6:$B$155,$A6,'Backlog completo'!$J$6:$J$155) | F6: =IFERROR(ROUND(AVERAGEIF('Backlog completo'!$B$6:$B$155,$A6,'Backlog completo'!$I$6:$I$155),0),0) | G6: Sprint 1 | H6: =IFERROR($E6/SUM($E$6:$E$26),0)
A7: EP-02 | B7: Estructura organizacional | C7: Representar la organización real del cliente: sus plantas, sus áreas, sus centros de costo y su gente. | D7: =COUNTIF('Backlog completo'!$B$6:$B$155,$A7) | E7: =SUMIF('Backlog completo'!$B$6:$B$155,$A7,'Backlog completo'!$J$6:$J$155) | F7: =IFERROR(ROUND(AVERAGEIF('Backlog completo'!$B$6:$B$155,$A7,'Backlog completo'!$I$6:$I$155),0),0) | G7: Sprint 1 | H7: =IFERROR($E7/SUM($E$6:$E$26),0)
A8: EP-03 | B8: Catálogos del sistema | C8: Que las listas de valores del sistema sean consistentes entre clientes y ampliables donde el negocio lo exige. | D8: =COUNTIF('Backlog completo'!$B$6:$B$155,$A8) | E8: =SUMIF('Backlog completo'!$B$6:$B$155,$A8,'Backlog completo'!$J$6:$J$155) | F8: =IFERROR(ROUND(AVERAGEIF('Backlog completo'!$B$6:$B$155,$A8,'Backlog completo'!$I$6:$I$155),0),0) | G8: Sprint 1 | H8: =IFERROR($E8/SUM($E$6:$E$26),0)
A9: EP-04 | B9: Maestro de activos y ubicación técnica | C9: Saber qué equipos existen, dónde están y de qué están compuestos. | D9: =COUNTIF('Backlog completo'!$B$6:$B$155,$A9) | E9: =SUMIF('Backlog completo'!$B$6:$B$155,$A9,'Backlog completo'!$J$6:$J$155) | F9: =IFERROR(ROUND(AVERAGEIF('Backlog completo'!$B$6:$B$155,$A9,'Backlog completo'!$I$6:$I$155),0),0) | G9: Sprint 2 | H9: =IFERROR($E9/SUM($E$6:$E$26),0)
A10: EP-05 | B10: Mediciones, medidores y variables de condición | C10: Capturar los valores que describen el estado de un equipo a lo largo del tiempo. | D10: =COUNTIF('Backlog completo'!$B$6:$B$155,$A10) | E10: =SUMIF('Backlog completo'!$B$6:$B$155,$A10,'Backlog completo'!$J$6:$J$155) | F10: =IFERROR(ROUND(AVERAGEIF('Backlog completo'!$B$6:$B$155,$A10,'Backlog completo'!$I$6:$I$155),0),0) | G10: Sprint 2 | H10: =IFERROR($E10/SUM($E$6:$E$26),0)
A11: EP-06 | B11: Repuestos, bodegas e inventario | C11: Saber qué repuestos hay, dónde están, cuántos quedan y cuánto duran. | D11: =COUNTIF('Backlog completo'!$B$6:$B$155,$A11) | E11: =SUMIF('Backlog completo'!$B$6:$B$155,$A11,'Backlog completo'!$J$6:$J$155) | F11: =IFERROR(ROUND(AVERAGEIF('Backlog completo'!$B$6:$B$155,$A11,'Backlog completo'!$I$6:$I$155),0),0) | G11: Sprint 3 | H11: =IFERROR($E11/SUM($E$6:$E$26),0)
A12: EP-07 | B12: Terceros, procedimientos y permisos de trabajo | C12: Registrar el trabajo que ejecuta un externo y la documentación que lo habilita. | D12: =COUNTIF('Backlog completo'!$B$6:$B$155,$A12) | E12: =SUMIF('Backlog completo'!$B$6:$B$155,$A12,'Backlog completo'!$J$6:$J$155) | F12: =IFERROR(ROUND(AVERAGEIF('Backlog completo'!$B$6:$B$155,$A12,'Backlog completo'!$I$6:$I$155),0),0) | G12: Sprint 3 | H12: =IFERROR($E12/SUM($E$6:$E$26),0)
A13: EP-08 | B13: Motor de programación | C13: Definir una sola vez cómo se repite el trabajo y qué planes, tareas y checklists lo reutilicen. | D13: =COUNTIF('Backlog completo'!$B$6:$B$155,$A13) | E13: =SUMIF('Backlog completo'!$B$6:$B$155,$A13,'Backlog completo'!$J$6:$J$155) | F13: =IFERROR(ROUND(AVERAGEIF('Backlog completo'!$B$6:$B$155,$A13,'Backlog completo'!$I$6:$I$155),0),0) | G13: Sprint 3 | H13: =IFERROR($E13/SUM($E$6:$E$26),0)
A14: EP-09 | B14: Planes de mantenimiento | C14: Trasladar el plan anual de la planta al sistema y que genere el trabajo por sí solo. | D14: =COUNTIF('Backlog completo'!$B$6:$B$155,$A14) | E14: =SUMIF('Backlog completo'!$B$6:$B$155,$A14,'Backlog completo'!$J$6:$J$155) | F14: =IFERROR(ROUND(AVERAGEIF('Backlog completo'!$B$6:$B$155,$A14,'Backlog completo'!$I$6:$I$155),0),0) | G14: Sprint 4 | H14: =IFERROR($E14/SUM($E$6:$E$26),0)
A15: EP-10 | B15: Checklist dinámico | C15: Que la planta diseñe sus propias pautas de inspección y que lo registrado sirva para algo más que archivar. | D15: =COUNTIF('Backlog completo'!$B$6:$B$155,$A15) | E15: =SUMIF('Backlog completo'!$B$6:$B$155,$A15,'Backlog completo'!$J$6:$J$155) | F15: =IFERROR(ROUND(AVERAGEIF('Backlog completo'!$B$6:$B$155,$A15,'Backlog completo'!$I$6:$I$155),0),0) | G15: Sprint 4 | H15: =IFERROR($E15/SUM($E$6:$E$26),0)
A16: EP-11 | B16: Tareas | C16: Registrar el trabajo programable que no interviene una máquina. | D16: =COUNTIF('Backlog completo'!$B$6:$B$155,$A16) | E16: =SUMIF('Backlog completo'!$B$6:$B$155,$A16,'Backlog completo'!$J$6:$J$155) | F16: =IFERROR(ROUND(AVERAGEIF('Backlog completo'!$B$6:$B$155,$A16,'Backlog completo'!$I$6:$I$155),0),0) | G16: Sprint 4 | H16: =IFERROR($E16/SUM($E$6:$E$26),0)
A17: EP-12 | B17: Órdenes de trabajo y fallas | C17: Gestionar el trabajo de mantenimiento desde que se detecta la necesidad hasta que se cierra. | D17: =COUNTIF('Backlog completo'!$B$6:$B$155,$A17) | E17: =SUMIF('Backlog completo'!$B$6:$B$155,$A17,'Backlog completo'!$J$6:$J$155) | F17: =IFERROR(ROUND(AVERAGEIF('Backlog completo'!$B$6:$B$155,$A17,'Backlog completo'!$I$6:$I$155),0),0) | G17: Sprint 5 | H17: =IFERROR($E17/SUM($E$6:$E$26),0)
... A26: EP-21 | B26: Operación comercial y de plataforma | C26: Vender, cobrar y sostener SIGMA como servicio: del primer contacto a la suscripción pagada, con procesos automáticos, correo confiable y una mesa de ayuda para el cliente. | D26: =COUNTIF('Backlog completo'!$B$6:$B$155,$A26) | E26: =SUMIF('Backlog completo'!$B$6:$B$155,$A26,'Backlog completo'!$J$6:$J$155) | F26: =IFERROR(ROUND(AVERAGEIF('Backlog completo'!$B$6:$B$155,$A26,'Backlog completo'!$I$6:$I$155),0),0) | G26: Sprint 5 | H26: =IFERROR($E26/SUM($E$6:$E$26),0)
B27: Total | D27: =SUM(D6:D26) | E27: =SUM(E6:E26) | H27: =SUM(H6:H26)

Sheet Sprint 1
A1: Sprint 1 · Fundaciones
A2: Del 02-09-2026 al 15-09-2026 · Acceso, seguridad, multicliente, estructura organizacional y catálogos.
A3: Historias | B3: =COUNTA($A$6:$A$22) | C3: Puntos comprometidos | D3: =SUM($I$6:$I$22) | E3: Puntos completados | F3: =SUM($O$6:$O$22) | G3: Avance | H3: =IFERROR(SUM($O$6:$O$22)/SUM($I$6:$I$22),0) | I3: Terminadas | J3: =COUNTIF($M$6:$M$22,"Terminada") | K3: Bloqueadas | L3: =COUNTIF($M$6:$M$22,"Bloqueada")
A5: ID | B5: Épica | C5: Historia de usuario | D5: Como | E5: Quiero | F5: Para | G5: Plataforma | H5: Valor | I5: Pts | J5: Prioridad | K5: Dependencias | L5: Escenarios | M5: Estado | N5: Responsable | O5: Pts completados | P5: Observaciones
A6: HU-001 | B6: EP-01 | C6: Iniciar sesión en SIGMA | D6: usuario de SIGMA | E6: ingresar con mi correo y mi contraseña | F6: acceder al sistema con la identidad y los permisos que me corresponden | G6: Web y App | H6: 95 | I6: 5 | J6: Alta | K6: Sin dependencias | L6: 4 | M6: Terminada | N6: Bryan Chávez | O6: =IF($M6="Terminada",$I6,0) | P6: Construida: contraseña con SHA2-256 y sal por usuario, bloqueo a los 5 intentos en 15 minutos, y rechazo en la puerta cuando la suscripción no está vigente o la cuenta no tiene perfil. PENDIENTE: que Catalina verifique los 4 criterios de aceptación.
A7: HU-006 | B7: EP-01 | C7: Aplicar mis permisos en la interfaz y en el servidor | D7: usuario con un perfil asignado | E7: ver solo los menús y acciones que puedo usar | F7: no perder tiempo en pantallas que el sistema va a rechazar | G7: Web y App | H7: 90 | I7: 5 | J7: Alta | K7: HU-001 | L7: 3 | M7: Terminada | N7: Emilio Fuentes | O7: =IF($M7="Terminada",$I7,0) | P7: Construida: la seguridad es por datos, una pantalla sin fila en Menus no se abre, y el permiso se revalida en el servidor. Se corrigió que un menú sin permiso asignado quedaba visible para cualquiera. PENDIENTE: verificación de los 3 criterios.
A8: HU-014 | B8: EP-02 | C8: Administrar usuarios del cliente | D8: administrador del cliente | E8: crear usuarios y asignarles perfil, plantas y especialidades | F8: que cada persona ingrese con lo que le corresponde | G8: Web | H8: 85 | I8: 8 | J8: Alta | K8: HU-011 | L8: 3 | M8: Terminada | N8: Bryan Chávez | O8: =IF($M8="Terminada",$I8,0) | P8: Construida y reparada: guardar fallaba por una función de base que no existía, la contraseña se guardaba sin cifrar y cambiar el perfil violaba una clave foránea. Los tres corregidos. PENDIENTE: verificación de los 3 criterios.
A9: HU-002 | B9: EP-01 | C9: Seleccionar cliente cuando pertenezco a más de uno | D9: usuario que trabaja para más de un cliente | E9: elegir con qué cliente voy a trabajar | F9: no mezclar información de dos empresas distintas | G9: Web y App | H9: 80 | I9: 3 | J9: Media | K9: HU-001 | L9: 3 | M9: Terminada | N9: Emilio Fuentes | O9: =IF($M9="Terminada",$I9,0) | P9: Construida: selector al entrar y chip de cliente en el encabezado. Solo Root, Soporte y Gerente Comercial ven todos los clientes; el resto ve los suyos. PENDIENTE: verificación de los 3 criterios.
A10: HU-015 | B10: EP-02 | C10: Administrar perfiles y sus permisos | D10: administrador del cliente | E10: definir qué puede hacer cada perfil | F10: reflejar en el sistema cómo se reparten las responsabilidades en la planta | G10: Web | H10: 80 | I10: 8 | J10: Media | K10: HU-006 | L10: 3 | M10: Terminada | N10: Bryan Chávez | O10: =IF($M10="Terminada",$I10,0) | P10: Construida: 7 perfiles base con su matriz de permisos. Un perfil de tipo Cliente ya no ve los nodos Sistema ni Comercial. Se definieron los que faltaban: Soporte, Gerente Comercial y Prevencionista. PENDIENTE: verificación de los 3 criterios.
A11: HU-011 | B11: EP-02 | C11: Administrar las plantas del cliente | D11: administrador del cliente | E11: registrar las plantas o instalaciones de la empresa | F11: poder separar la operación por ubicación física | G11: Web | H11: 75 | I11: 5 | J11: Media | K11: HU-010 | L11: 2 | M11: Terminada | N11: Emilio Fuentes | O11: =IF($M11="Terminada",$I11,0) | P11: Construida: ficha única de planta. Se retiró una segunda ficha que al guardar borraba la zona horaria y las coordenadas. Geocodifica la dirección con Google Maps. PENDIENTE: verificación de los 2 criterios.
A12: HU-012 | B12: EP-02 | C12: Administrar las áreas de una planta | D12: administrador del cliente | E12: organizar la planta en áreas y subareas | F12: agrupar activos e indicadores por zona productiva | G12: Web | H12: 75 | I12: 5 | J12: Media | K12: HU-011 | L12: 2 | M12: Terminada | N12: Bryan Chávez | O12: =IF($M12="Terminada",$I12,0) | P12: Construida: jerarquía de áreas con detección de ciclos. PENDIENTE: verificación de los 2 criterios.
A13: HU-003 | B13: EP-01 | C13: Cerrar sesión y expirar la sesión inactiva | D13: usuario de SIGMA | E13: que mi sesión se cierre cuando dejo de usar el sistema | F13: que nadie use mi cuenta si dejo el equipo abierto en planta | G13: Web y App | H13: 70 | I13: 3 | J13: Media | K13: HU-001 | L13: 3 | M13: Terminada | N13: Emilio Fuentes | O13: =IF($M13="Terminada",$I13,0) | P13: Construida: sesión a 30 minutos y cabeceras anti-caché para que el botón Atrás no repinte la pantalla anterior. OJO: el criterio 3 (la app conserva el trabajo pendiente) no se puede verificar todavía, la app no existe.
A14: HU-010 | B14: EP-02 | C14: Administrar clientes de SIGMA | D14: administrador de SIGMA | E14: dar de alta y mantener los clientes de la plataforma | F14: incorporar una empresa nueva sin intervenir la base de datos | G14: Web | H14: 70 | I14: 5 | J14: Media | K14: Sin dependencias | L14: 2 | M14: Terminada | N14: Bryan Chávez | O14: =IF($M14="Terminada",$I14,0) | P14: Construida: alta con identificador validado por país (RUT, RUC, CUIT, NIT). Se resolvió la duda abierta: eliminar un cliente es BAJA LÓGICA, porque hay períodos emitidos y pagos apuntando a él. PENDIENTE: verificación de los 2 criterios.
A15: HU-017 | B15: EP-02 | C15: Registrar especialidades y certificaciones de un usuario | D15: administrador del cliente | E15: registrar que sabe hacer cada técnico y hasta cuando está certificado | F15: no asignar un trabajo a alguien cuya certificación venció | G15: Web | H15: 70 | I15: 5 | J15: Media | K15: HU-014 | L15: 3 | M15: Terminada | N15: Emilio Fuentes | O15: =IF($M15="Terminada",$I15,0) | P15: Construida: especialidades por usuario con nivel, certificación y vencimiento. PENDIENTE: verificación, sobre todo el aviso anticipado.
A16: HU-007 | B16: EP-01 | C16: Otorgar un permiso puntual a un usuario | D16: administrador del cliente | E16: conceder o revocar un permiso específico a una persona sin cambiar su perfil | F16: resolver excepciones sin crear un perfil nuevo por cada caso particular | G16: Web | H16: 65 | I16: 5 | J16: Media | K16: HU-006 | L16: 3 | M16: Terminada | N16: Bryan Chávez | O16: =IF($M16="Terminada",$I16,0) | P16: Construida: excepción por usuario con vigencia y ámbito por planta. Denegar prevalece sobre lo que otorga el perfil. PENDIENTE: verificación de los 3 criterios.
A17: HU-016 | B17: EP-02 | C17: Administrar grupos de trabajo | D17: administrador del cliente | E17: agrupar técnicos en cuadrillas o turnos | F17: poder asignar trabajo al turno completo y no a una persona en particular | G17: Web | H17: 65 | I17: 5 | J17: Media | K17: HU-014 | L17: 3 | M17: Terminada | N17: Emilio Fuentes | O17: =IF($M17="Terminada",$I17,0) | P17: Construida: grupos con un solo líder vigente por ventana de fechas. PENDIENTE: verificación de los 3 criterios.
... A22: HU-020 | B22: EP-03 | C22: Consultar los catálogos del sistema | D22: administrador del cliente | E22: consultar los valores disponibles de cada catálogo | F22: saber qué opciones va a ver el usuario antes de configurar el sistema | G22: Web | H22: 40 | I22: 3 | J22: Baja | K22: Sin dependencias | L22: 2 | M22: Terminada | N22: Bryan Chávez | O22: =IF($M22="Terminada",$I22,0) | P22: Construida: consulta y búsqueda transversal de catálogos. PENDIENTE: verificación de los 2 criterios.
C23: Total Sprint 1 | I23: =SUM(I6:I22) | O23: =SUM(O6:O22)

Sheet Sprint 2
A1: Sprint 2 · Activos
A2: Del 16-09-2026 al 29-09-2026 · Maestro de activos, ubicación técnica, mediciones y sincronización inicial de la app.
A3: Historias | B3: =COUNTA($A$6:$A$23) | C3: Puntos comprometidos | D3: =SUM($I$6:$I$23) | E3: Puntos completados | F3: =SUM($O$6:$O$23) | G3: Avance | H3: =IFERROR(SUM($O$6:$O$23)/SUM($I$6:$I$23),0) | I3: Terminadas | J3: =COUNTIF($M$6:$M$23,"Terminada") | K3: Bloqueadas | L3: =COUNTIF($M$6:$M$27,"Bloqueada")
A5: ID | B5: Épica | C5: Historia de usuario | D5: Como | E5: Quiero | F5: Para | G5: Plataforma | H5: Valor | I5: Pts | J5: Prioridad | K5: Dependencias | L5: Escenarios | M5: Estado | N5: Responsable | O5: Pts completados | P5: Observaciones
A6: HU-035 | B6: EP-04 | C6: Registrar un activo | D6: planificador | E6: dar de alta un equipo con su ficha técnica completa | F6: tener el inventario de máquinas sobre el cual se planifica todo el mantenimiento | G6: Web | H6: 100 | I6: 8 | J6: Alta | K6: HU-033, HU-032 | L6: 4 | M6: Terminada | N6: Emilio Fuentes | O6: =IF($M6="Terminada",$I6,0)
A7: HU-042 | B7: EP-05 | C7: Configurar el medidor de un activo | D7: planificador | E7: registrar el horómetro o contador de un equipo | F7: poder programar mantenimiento por horas de uso y no solo por calendario | G7: Web | H7: 95 | I7: 3 | J7: Alta | K7: HU-035 | L7: 3 | M7: Terminada | N7: Emilio Fuentes | O7: =IF($M7="Terminada",$I7,0)
A8: HU-037 | B8: EP-04 | C8: Consultar la ficha y el historial de un activo | D8: usuario de mantenimiento | E8: ver toda la vida de un equipo en una sola pantalla | F8: entender qué le ha pasado antes de intervenirlo | G8: Web y App | H8: 90 | I8: 5 | J8: Alta | K8: HU-035 | L8: 3 | M8: Terminada | N8: Emilio Fuentes | O8: =IF($M8="Terminada",$I8,0)
A9: HU-033 | B9: EP-04 | C9: Registrar una posición funcional | D9: planificador | E9: definir posiciones funcionales estables dentro de cada área | F9: que el código QR pegado en la sala siga sirviendo aunque se cambie la máquina | G9: Web | H9: 85 | I9: 5 | J9: Alta | K9: HU-012 | L9: 2 | M9: Terminada | N9: Bryan Chávez | O9: =IF($M9="Terminada",$I9,0)
A10: HU-036 | B10: EP-04 | C10: Registrar los componentes de un activo | D10: planificador | E10: desglosar el equipo en sus componentes | F10: saber qué pieza falló y cuánto duró, no solo que falló la máquina | G10: Web | H10: 80 | I10: 5 | J10: Media | K10: HU-035 | L10: 3 | M10: Terminada | N10: Emilio Fuentes | O10: =IF($M10="Terminada",$I10,0)
A11: HU-193 | B11: EP-19 | C11: Bloquear el acceso por suscripción vencida | D11: administrador de SIGMA | E11: que el sistema restrinja el acceso cuando la suscripción vence | F11: sostener el modelo comercial sin intervenir manualmente cada cliente | G11: Web y App | H11: 80 | I11: 5 | J11: Media | K11: HU-191 | L11: 4 | M11: Terminada | N11: Bryan Chávez | O11: =IF($M11="Terminada",$I11,0)
A12: HU-038 | B12: EP-04 | C12: Cambiar el estado de un activo indicando el motivo | D12: supervisor de mantenimiento | E12: registrar cuando un equipo sale o vuelve a operación | F12: que la disponibilidad calculada corresponda a lo que realmente paso | G12: Web y App | H12: 75 | I12: 3 | J12: Media | K12: HU-035 | L12: 2 | M12: Terminada | N12: Emilio Fuentes | O12: =IF($M12="Terminada",$I12,0)
A13: HU-191 | B13: EP-19 | C13: Contratar o renovar una suscripción | D13: administrador de SIGMA | E13: registrar la contratación o renovación de un cliente | F13: mantener vigente el servicio y su historial comercial | G13: Web | H13: 75 | I13: 5 | J13: Media | K13: HU-190 | L13: 2 | M13: Terminada | N13: Bryan Chávez | O13: =IF($M13="Terminada",$I13,0)
A14: HU-034 | B14: EP-04 | C14: Generar e imprimir el código QR de una posición | D14: planificador | E14: imprimir el código QR de una posición | F14: que el técnico llegue a la máquina y acceda a su ficha escaneándolo | G14: Web | H14: 70 | I14: 3 | J14: Media | K14: HU-033 | L14: 2 | M14: Terminada | N14: Bryan Chávez | O14: =IF($M14="Terminada",$I14,0)
A15: HU-045 | B15: EP-05 | C15: Consultar la serie histórica de una variable | D15: jefe de mantenimiento | E15: ver cómo ha evolucionado una variable en el tiempo | F15: reconocer una tendencia antes de que se convierta en una falla | G15: Web | H15: 70 | I15: 5 | J15: Media | K15: HU-044 | L15: 2 | M15: Terminada | N15: Bryan Chávez | O15: =IF($M15="Terminada",$I15,0)
A16: HU-190 | B16: EP-19 | C16: Administrar planes comerciales | D16: administrador de SIGMA | E16: definir los planes que se ofrecen y que incluye cada uno | F16: poder vender el producto con condiciones claras | G16: Web | H16: 70 | I16: 5 | J16: Media | K16: Sin dependencias | L16: 3 | M16: Terminada | N16: Bryan Chávez | O16: =IF($M16="Terminada",$I16,0)
A17: HU-194 | B17: EP-19 | C17: Registrar el pago de una suscripción | D17: administrador del cliente | E17: informar el pago adjuntando el comprobante | F17: recuperar el servicio sin depender de una gestión telefonica | G17: Web | H17: 70 | I17: 5 | J17: Media | K17: HU-193 | L17: 3 | M17: Terminada | N17: Bryan Chávez | O17: =IF($M17="Terminada",$I17,0)
... A23: HU-032 | B23: EP-04 | C23: Definir los atributos técnicos de un tipo de activo | D23: planificador | E23: definir qué datos técnicos se registran para cada tipo de equipo | F23: que la ficha de un blower pida potencia y caudal, y la de un motor pida otra cosa | G23: Web | H23: 55 | I23: 5 | J23: Baja | K23: HU-030 | L23: 2 | M23: Terminada | N23: Emilio Fuentes | O23: =IF($M23="Terminada",$I23,0)
C24: Total Sprint 2 | I24: =SUM(I6:I27) | O24: =SUM(O6:O27)

Sheet Sprint 3
A1: Sprint 3 · Recursos y recurrencia
A2: Del 30-09-2026 al 13-10-2026 · Repuestos e inventario, terceros y procedimientos, motor de programación.
A3: Historias | B3: =COUNTA($A$6:$A$33) | C3: Puntos comprometidos | D3: =SUM($I$6:$I$33) | E3: Puntos completados | F3: =SUM($O$6:$O$33) | G3: Avance | H3: =IFERROR(SUM($O$6:$O$33)/SUM($I$6:$I$33),0) | I3: Terminadas | J3: =COUNTIF($M$6:$M$33,"Terminada") | K3: Bloqueadas | L3: =COUNTIF($M$6:$M$34,"Bloqueada")
A5: ID | B5: Épica | C5: Historia de usuario | D5: Como | E5: Quiero | F5: Para | G5: Plataforma | H5: Valor | I5: Pts | J5: Prioridad | K5: Dependencias | L5: Escenarios | M5: Estado | N5: Responsable | O5: Pts completados | P5: Observaciones
A6: HU-073 | B6: EP-08 | C6: Crear una programación por medidor | D6: planificador | E6: programar un trabajo cada cierta cantidad de horas o ciclos | F6: que el mantenimiento se dispare por uso real y no por calendario | G6: Web | H6: 95 | I6: 8 | J6: Alta | K6: HU-042 | L6: 3 | M6: Terminada | N6: Bryan Chávez | O6: =IF($M6="Terminada",$I6,0)
A7: HU-076 | B7: EP-08 | C7: Generar las ocurrencias de forma automática | D7: planificador | E7: que el sistema genere solo las ocurrencias futuras | F7: no tener que crear a mano cada mantención del año | G7: Servidor | H7: 95 | I7: 8 | J7: Alta | K7: HU-071, HU-073 | L7: 4 | M7: Terminada | N7: Bryan Chávez | O7: =IF($M7="Terminada",$I7,0)
A8: HU-071 | B8: EP-08 | C8: Crear una programación de calendario | D8: planificador | E8: programar un trabajo que se repite según el calendario | F8: cubrir rutinas diarias, semanales, mensuales y anuales | G8: Web | H8: 90 | I8: 8 | J8: Alta | K8: Sin dependencias | L8: 3 | M8: Terminada | N8: Bryan Chávez | O8: =IF($M8="Terminada",$I8,0)
A9: HU-053 | B9: EP-06 | C9: Definir el stock mínimo y máximo de un repuesto | D9: bodeguero | E9: establecer los umbrales de existencia de cada repuesto por bodega | F9: que el sistema avise antes de quedarme sin una pieza crítica | G9: Web | H9: 85 | I9: 3 | J9: Alta | K9: HU-052 | L9: 3 | M9: Terminada | N9: Bryan Chávez | O9: =IF($M9="Terminada",$I9,0)
A10: HU-055 | B10: EP-06 | C10: Entregar repuestos contra una orden de trabajo | D10: bodeguero | E10: entregar repuestos asociándolos a la orden que los consume | F10: saber cuánto costo de repuestos tuvo cada intervención | G10: Web y App | H10: 85 | I10: 5 | J10: Alta | K10: HU-054 | L10: 3 | M10: Terminada | N10: Bryan Chávez | O10: =IF($M10="Terminada",$I10,0)
A11: HU-050 | B11: EP-06 | C11: Administrar el maestro de repuestos | D11: bodeguero | E11: mantener el catálogo de repuestos de la planta | F11: que todos nombren la misma pieza de la misma forma | G11: Web | H11: 80 | I11: 5 | J11: Media | K11: Sin dependencias | L11: 2 | M11: Terminada | N11: Bryan Chávez | O11: =IF($M11="Terminada",$I11,0)
A12: HU-056 | B12: EP-06 | C12: Consultar la existencia de un repuesto | D12: usuario de mantenimiento | E12: saber cuántas unidades hay y dónde están | F12: no detener un trabajo por ir a buscar una pieza que no está | G12: Web y App | H12: 80 | I12: 3 | J12: Media | K12: HU-054 | L12: 2 | M12: Terminada | N12: Bryan Chávez | O12: =IF($M12="Terminada",$I12,0)
A13: HU-075 | B13: EP-08 | C13: Definir tolerancias y exclusiones de una programación | D13: planificador | E13: indicar cuánto se puede adelantar o atrasar un trabajo y que días no aplica | F13: que el indicador de cumplimiento refleje la realidad de la planta | G13: Web | H13: 80 | I13: 5 | J13: Media | K13: Sin dependencias | L13: 3 | M13: Terminada | N13: Bryan Chávez | O13: =IF($M13="Terminada",$I13,0)
A14: HU-054 | B14: EP-06 | C14: Registrar el ingreso de repuestos a bodega | D14: bodeguero | E14: registrar la recepción de repuestos con su lote y documento | F14: que la existencia del sistema coincida con la de la estantería | G14: Web y App | H14: 75 | I14: 5 | J14: Media | K14: HU-052 | L14: 2 | M14: Terminada | N14: Bryan Chávez | O14: =IF($M14="Terminada",$I14,0)
A15: HU-060 | B15: EP-07 | C15: Administrar proveedores | D15: jefe de mantenimiento | E15: mantener el registro de las empresas que prestan servicios | F15: poder sumar al cierre del año cuánto se gastó en cada contratista | G15: Web | H15: 75 | I15: 5 | J15: Media | K15: Sin dependencias | L15: 2 | M15: Terminada | N15: Bryan Chávez | O15: =IF($M15="Terminada",$I15,0)
A16: HU-051 | B16: EP-06 | C16: Definir la compatibilidad de un repuesto | D16: planificador | E16: indicar en qué equipos o modelos aplica cada repuesto | F16: que el técnico no monte una pieza que no corresponde | G16: Web | H16: 70 | I16: 3 | J16: Media | K16: HU-050 | L16: 2 | M16: Terminada | N16: Bryan Chávez | O16: =IF($M16="Terminada",$I16,0)
A17: HU-052 | B17: EP-06 | C17: Administrar bodegas y ubicaciones | D17: bodeguero | E17: definir las bodegas y sus ubicaciones internas | F17: saber en qué estante está el repuesto y no solo que existe | G17: Web | H17: 70 | I17: 5 | J17: Media | K17: HU-011 | L17: 2 | M17: Terminada | N17: Bryan Chávez | O17: =IF($M17="Terminada",$I17,0)
... A27: HU-064 | B27: EP-07 | C27: Consultar permisos vigentes y por vencer | D27: jefe de mantenimiento | E27: ver qué permisos están vigentes y cuáles están por vencer | F27: no descubrir en terreno que el permiso caducó | G27: Web | H27: 55 | I27: 3 | J27: Baja | K27: HU-063 | L27: 2 | M27: Terminada | N27: Bryan Chávez | O27: =IF($M27="Terminada",$I27,0)
A28: HU-059 | B28: EP-06 | C28: Saber en qué estante y de qué lote está cada repuesto | D28: bodeguero | E28: que la existencia se lleve por ubicación y por lote, no solo por bodega | F28: poder ir directo al estante y saber qué lote tomar antes de que venza | G28: Web y App | H28: 90 | I28: 8 | J28: Alta | K28: HU-052, HU-056 | L28: 4 | M28: Terminada | N28: Bryan Chávez | O28: =IF($M28="Terminada",$I28,0) | P28: Trabajo no planificado: construido y verificado. Cierra con sus pruebas.
A29: HU-066 | B29: EP-06 | C29: Identificar bodegas, ubicaciones y repuestos con etiquetas QR | D29: bodeguero | E29: imprimir etiquetas con código y QR para pegar en estantes y repuestos | F29: rotular la bodega una vez y no volver a buscar a mano lo que hay en cada sitio | G29: Web | H29: 80 | I29: 5 | J29: Media | K29: HU-059 | L29: 3 | M29: Terminada | N29: Bryan Chávez | O29: =IF($M29="Terminada",$I29,0) | P29: Trabajo no planificado: construido y verificado. Cierra con sus pruebas.
A30: HU-067 | B30: EP-06 | C30: Consultar escaneando una etiqueta | D30: bodeguero | E30: apuntar la cámara del teléfono a una etiqueta y ver qué hay en ese lugar | F30: consultar de pie frente al estante sin volver a la oficina | G30: Web y App | H30: 85 | I30: 5 | J30: Alta | K30: HU-066 | L30: 3 | M30: Terminada | N30: Bryan Chávez | O30: =IF($M30="Terminada",$I30,0) | P30: Trabajo no planificado: construido y verificado. Cierra con sus pruebas.
A31: HU-068 | B31: EP-06 | C31: Cargar y descargar el maestro de repuestos en planilla | D31: administrador de cliente | E31: dar de alta muchos repuestos desde un Excel y bajar los que ya existen | F31: poner en marcha el inventario sin teclear quinientas fichas una por una | G31: Web | H31: 75 | I31: 5 | J31: Media | K31: HU-050 | L31: 2 | M31: Terminada | N31: Bryan Chávez | O31: =IF($M31="Terminada",$I31,0) | P31: Trabajo no planificado: construido y verificado. Cierra con sus pruebas.
A32: HU-069 | B32: EP-06 | C32: Generar los códigos automáticamente | D32: administrador de cliente | E32: que el código de cada registro se genere solo con el prefijo de su módulo | F32: no depender de que cada persona invente un formato distinto | G32: Web | H32: 60 | I32: 3 | J32: Media | K32: Sin dependencias | L32: 2 | M32: Terminada | N32: Bryan Chávez | O32: =IF($M32="Terminada",$I32,0) | P32: Trabajo no planificado: construido y verificado. Cierra con sus pruebas.
A33: HU-077 | B33: EP-06 | C33: Que el sistema avise lo que encuentra | D33: jefe de mantenimiento | E33: que el sistema detecte solo los problemas de operación y me los notifique | F33: enterarme de un quiebre de stock cuando ocurre y no cuando alguien lo reporta | G33: Web y App | H33: 95 | I33: 8 | J33: Alta | K33: HU-053 | L33: 4 | M33: Terminada | N33: Bryan Chávez | O33: =IF($M33="Terminada",$I33,0) | P33: Trabajo no planificado: construido y verificado. Cierra con sus pruebas.

Sheet Sprint 4
A1: Sprint 4 · Trabajo planificado
A2: Del 14-10-2026 al 27-10-2026 · Planes de mantenimiento, checklist dinámico y tareas.
A3: Historias | B3: =COUNTA($A$6:$A$24) | C3: Puntos comprometidos | D3: =SUM($I$6:$I$24) | E3: Puntos completados | F3: =SUM($O$6:$O$24) | G3: Avance | H3: =IFERROR(SUM($O$6:$O$24)/SUM($I$6:$I$24),0) | I3: Terminadas | J3: =COUNTIF($M$6:$M$24,"Terminada") | K3: Bloqueadas | L3: =COUNTIF($M$6:$M$29,"Bloqueada")
A5: ID | B5: Épica | C5: Historia de usuario | D5: Como | E5: Quiero | F5: Para | G5: Plataforma | H5: Valor | I5: Pts | J5: Prioridad | K5: Dependencias | L5: Escenarios | M5: Estado | N5: Responsable | O5: Pts completados | P5: Observaciones
A6: HU-080 | B6: EP-09 | C6: Crear un plan de mantenimiento | D6: planificador | E6: definir un plan de mantenimiento para una familia de equipos | F6: dejar de administrar el plan anual en una planilla | G6: Web | H6: 100 | I6: 8 | J6: Alta | K6: HU-031 | L6: 2 | M6: Terminada | N6: Bryan Chávez | O6: =IF($M6="Terminada",$I6,0)
A7: HU-081 | B7: EP-09 | C7: Definir los hitos de un plan | D7: planificador | E7: agrupar las actividades del plan en hitos programados | F7: que al llegar a las 500 horas se genere una sola orden con todas sus actividades | G7: Web | H7: 100 | I7: 8 | J7: Alta | K7: HU-080, HU-073 | L7: 4 | M7: Terminada | N7: Bryan Chávez | O7: =IF($M7="Terminada",$I7,0)
A8: HU-082 | B8: EP-09 | C8: Definir las actividades de un hito | D8: planificador | E8: detallar que se hace en cada hito | F8: que el técnico reciba la instrucción concreta y los repuestos que va a necesitar | G8: Web | H8: 95 | I8: 8 | J8: Alta | K8: HU-081, HU-062 | L8: 4 | M8: Terminada | N8: Bryan Chávez | O8: =IF($M8="Terminada",$I8,0)
A9: HU-090 | B9: EP-10 | C9: Diseñar una plantilla de checklist | D9: planificador | E9: construir la pauta de inspección con mis propias preguntas | F9: que el checklist refleje lo que esta planta necesita revisar | G9: Web | H9: 95 | I9: 13 | J9: Alta | K9: HU-041 | L9: 4 | M9: Terminada | N9: Emilio Fuentes | O9: =IF($M9="Terminada",$I9,0)
A10: HU-096 | B10: EP-10 | C10: Revisar los hallazgos generados por un checklist | D10: planificador | E10: decidir qué hacer con lo que encontró la inspección | F10: que un hallazgo termine en una acción y no en un archivo que nadie abre | G10: Web | H10: 95 | I10: 5 | J10: Alta | K10: HU-095 | L10: 3 | M10: Terminada | N10: Bryan Chávez | O10: =IF($M10="Terminada",$I10,0)
A11: HU-083 | B11: EP-09 | C11: Asociar activos a un plan | D11: planificador | E11: indicar a qué equipos aplica el plan | F11: aplicar un mismo plan a varias máquinas identicas sin duplicarlo | G11: Web | H11: 90 | I11: 5 | J11: Alta | K11: HU-080, HU-042 | L11: 3 | M11: Terminada | N11: Bryan Chávez | O11: =IF($M11="Terminada",$I11,0)
A12: HU-084 | B12: EP-09 | C12: Publicar una versión del plan | D12: planificador | E12: publicar el plan para que empiece a generar trabajo | F12: que el contenido quede congelado y las órdenes históricas sean reconstruibles | G12: Web | H12: 90 | I12: 5 | J12: Alta | K12: HU-082, HU-083 | L12: 5 | M12: Terminada | N12: Bryan Chávez | O12: =IF($M12="Terminada",$I12,0)
A13: HU-091 | B13: EP-10 | C13: Definir los umbrales y las acciones de un ítem | D13: planificador | E13: establecer que valores son normales y que ocurre cuando no lo son | F13: que una lectura fuera de rango produzca una consecuencia y no solo un número anotado | G13: Web | H13: 90 | I13: 8 | J13: Alta | K13: HU-090 | L13: 4 | M13: Terminada | N13: Catalina Pescio | O13: =IF($M13="Terminada",$I13,0)
A14: HU-086 | B14: EP-09 | C14: Reprogramar una ocurrencia indicando el motivo | D14: planificador | E14: mover una mantención de fecha dejando registro | F14: que el indicador de cumplimiento no se pueda maquillar moviendo fechas | G14: Web | H14: 85 | I14: 5 | J14: Alta | K14: HU-084 | L14: 3 | M14: Terminada | N14: Emilio Fuentes | O14: =IF($M14="Terminada",$I14,0)
A15: HU-087 | B15: EP-09 | C15: Consultar la bandeja de ocurrencias pendientes | D15: planificador | E15: ver qué mantenciones están por vencer o vencidas | F15: anticiparme antes de que el trabajo se acumule | G15: Web | H15: 85 | I15: 5 | J15: Alta | K15: HU-076 | L15: 3 | M15: Terminada | N15: Bryan Chávez | O15: =IF($M15="Terminada",$I15,0)
A16: HU-093 | B16: EP-10 | C16: Publicar una versión de checklist | D16: planificador | E16: publicar la plantilla para que se pueda ejecutar | F16: que las ejecuciones históricas conserven las preguntas que realmente se aplicaron | G16: Web | H16: 85 | I16: 5 | J16: Alta | K16: HU-091 | L16: 3 | M16: Terminada | N16: Emilio Fuentes | O16: =IF($M16="Terminada",$I16,0)
A17: HU-094 | B17: EP-10 | C17: Programar un checklist recurrente | D17: planificador | E17: programar la ejecución periódica de un checklist | F17: que la ronda diaria aparezca sola en la bandeja del técnico | G17: Web | H17: 85 | I17: 5 | J17: Alta | K17: HU-093, HU-071 | L17: 3 | M17: Terminada | N17: Emilio Fuentes | O17: =IF($M17="Terminada",$I17,0)
... A24: HU-104 | B24: EP-11 | C24: Comentar una tarea | D24: usuario de mantenimiento | E24: dejar comentarios en el hilo de una tarea | F24: coordinar sin salir del sistema y conservar lo que se acordó | G24: Web y App | H24: 45 | I24: 3 | J24: Baja | K24: HU-103 | L24: 2 | M24: Terminada | N24: Bryan Chávez | O24: =IF($M24="Terminada",$I24,0)
C25: Total Sprint 4 | I25: =SUM(I6:I29) | O25: =SUM(O6:O29)

Sheet Sprint 5
A1: Sprint 5 · Ejecución
A2: Del 28-10-2026 al 10-11-2026 · Órdenes de trabajo, fallas, bitácora, evidencias, terreno sin conexión y voz.
A3: Historias | B3: =COUNTA($A$6:$A$31) | C3: Puntos comprometidos | D3: =SUM($I$6:$I$31) | E3: Puntos completados | F3: =SUM($O$6:$O$31) | G3: Avance | H3: =IFERROR(SUM($O$6:$O$31)/SUM($I$6:$I$31),0) | I3: Terminadas | J3: =COUNTIF($M$6:$M$31,"Terminada") | K3: Bloqueadas | L3: =COUNTIF($M$6:$M$31,"Bloqueada")
A5: ID | B5: Épica | C5: Historia de usuario | D5: Como | E5: Quiero | F5: Para | G5: Plataforma | H5: Valor | I5: Pts | J5: Prioridad | K5: Dependencias | L5: Escenarios | M5: Estado | N5: Responsable | O5: Pts completados | P5: Observaciones
A6: HU-110 | B6: EP-12 | C6: Crear una orden de trabajo correctiva | D6: técnico, supervisor, jefe o planificador | E6: registrar una necesidad de intervención | F6: que el trabajo quede en el sistema desde el momento en que se detecta | G6: Web y App | H6: 100 | I6: 8 | J6: Alta | K6: HU-035 | L6: 4 | M6: Terminada | N6: Bryan Chávez | O6: =IF($M6="Terminada",$I6,0)
A7: HU-111 | B7: EP-12 | C7: Generar una orden desde la ocurrencia de un plan | D7: planificador | E7: materializar en una orden la mantención que corresponde ejecutar | F7: que el plan se traduzca en trabajo concreto sin volver a escribirlo | G7: Web | H7: 95 | I7: 5 | J7: Alta | K7: HU-087, HU-110 | L7: 3 | M7: Terminada | N7: Bryan Chávez | O7: =IF($M7="Terminada",$I7,0)
A8: HU-120 | B8: EP-12 | C8: Cerrar una orden de trabajo | D8: planificador, supervisor o jefe de mantenimiento | E8: cerrar formalmente la orden | F8: que el trabajo quede contabilizado y el equipo vuelva a su estado operativo | G8: Web | H8: 95 | I8: 5 | J8: Alta | K8: HU-119 | L8: 4 | M8: Terminada | N8: Bryan Chávez | O8: =IF($M8="Terminada",$I8,0)
A9: HU-112 | B9: EP-12 | C9: Asignar una orden de trabajo | D9: planificador o supervisor | E9: asignar la orden a un técnico, a un grupo o a una empresa externa | F9: que quede claro quién es responsable de ejecutarla | G9: Web | H9: 90 | I9: 5 | J9: Alta | K9: HU-110, HU-060 | L9: 4 | M9: Terminada | N9: Bryan Chávez | O9: =IF($M9="Terminada",$I9,0)
A10: HU-122 | B10: EP-12 | C10: Consultar la bandeja de órdenes en espera de cierre | D10: planificador | E10: ver el trabajo terminado que todavía no he cerrado | F10: tener a la vista mi propio pendiente y no dejar órdenes abiertas por meses | G10: Web | H10: 90 | I10: 3 | J10: Alta | K10: HU-119 | L10: 2 | M10: Terminada | N10: Bryan Chávez | O10: =IF($M10="Terminada",$I10,0)
A11: HU-117 | B11: EP-12 | C11: Registrar los servicios contratados en una orden | D11: jefe de mantenimiento | E11: registrar lo que se le pagó a un tercero por esta intervención | F11: poder sumar el gasto en contratistas al cierre del periodo | G11: Web | H11: 85 | I11: 5 | J11: Alta | K11: HU-110, HU-060 | L11: 3 | M11: Terminada | N11: Bryan Chávez | O11: =IF($M11="Terminada",$I11,0)
A12: HU-123 | B12: EP-12 | C12: Registrar una falla y su diagnóstico | D12: técnico o supervisor de mantenimiento | E12: registrar qué se rompió, cómo falló y por qué | F12: poder analizar después las causas que más repiten y atacarlas | G12: Web y App | H12: 80 | I12: 8 | J12: Media | K12: HU-110 | L12: 4 | M12: Terminada | N12: Bryan Chávez | O12: =IF($M12="Terminada",$I12,0)
A13: HU-124 | B13: EP-12 | C13: Registrar la indisponibilidad de un equipo | D13: supervisor de mantenimiento | E13: registrar el tiempo en que un equipo no estuvo disponible | F13: poder calcular la disponibilidad real y no un promedio sin sustento | G13: Web y App | H13: 80 | I13: 5 | J13: Media | K13: HU-035 | L13: 3 | M13: Terminada | N13: Bryan Chávez | O13: =IF($M13="Terminada",$I13,0)
A14: HU-118 | B14: EP-12 | C14: Registrar las firmas de aceptación, ejecución y validación | D14: supervisor o jefe de mantenimiento | E14: dejar constancia de quién recibió, ejecutó y aprobó el trabajo | F14: que la orden tenga el mismo respaldo que el formulario en papel que reemplaza | G14: Web y App | H14: 70 | I14: 5 | J14: Media | K14: HU-114 | L14: 3 | M14: Terminada | N14: Bryan Chávez | O14: =IF($M14="Terminada",$I14,0)
A15: HU-142 | B15: EP-14 | C15: Consultar la galería de evidencias | D15: usuario de mantenimiento | E15: ver todas las fotografías asociadas a una orden o a un equipo | F15: entender el estado del equipo antes de intervenirlo | G15: Web y App | H15: 70 | I15: 5 | J15: Media | K15: HU-140 | L15: 2 | M15: Terminada | N15: Catalina Pescio | O15: =IF($M15="Terminada",$I15,0) | P15: Galería de evidencias en la ficha de la OT y del activo (web) y GET /api/archivo-vinculos para la app (BD/429–436). Tareas de Catalina terminadas; el consumo desde la app (T-5257) pasó al Sprint 6. Pendiente validación de la PO.
A16: HU-143 | B16: EP-14 | C16: Definir imágenes de referencia | D16: planificador | E16: adjuntar la fotografía de como debe quedar un trabajo | F16: que el técnico compare contra un estándar y no contra su criterio | G16: Web | H16: 70 | I16: 3 | J16: Media | K16: HU-140 | L16: 3 | M16: Terminada | N16: Catalina Pescio | O16: =IF($M16="Terminada",$I16,0) | P16: Imagen de referencia en la actividad del plan y en el ítem de pauta; la ve quien ejecuta en la OT y en la inspección (BD/454). Pendiente validación de la PO.
A17: HU-125 | B17: EP-12 | C17: Imprimir una orden de trabajo | D17: jefe de mantenimiento | E17: imprimir la orden en el formato que usa la planta | F17: entregarla en papel cuando el trabajo lo requiere | G17: Web | H17: 60 | I17: 5 | J17: Baja | K17: HU-120 | L17: 2 | M17: Terminada | N17: Bryan Chávez | O17: =IF($M17="Terminada",$I17,0)
A18: HU-131 | B18: EP-13 | C18: Comentar y rectificar una entrada de bitácora | D18: usuario de mantenimiento | E18: comentar una entrada o corregirla sin borrar lo escrito | F18: que la corrección sea visible y no un reemplazo silencioso | G18: Web y App | H18: 60 | I18: 5 | J18: Baja | K18: HU-130 | L18: 3 | M18: Terminada | N18: Emilio Fuentes | O18: =IF($M18="Terminada",$I18,0)
A19: HU-162 | B19: EP-16 | C19: Configurar las opciones de accesibilidad | D19: usuario de SIGMA | E19: ajustar tamaño de texto, contraste, voz y sonidos | F19: poder usar el sistema según mis condiciones de trabajo y mis capacidades | G19: App y Web | H19: 55 | I19: 5 | J19: Baja | K19: HU-160 | L19: 4 | M19: Terminada | N19: Emilio Fuentes | O19: =IF($M19="Terminada",$I19,0)
A20: HU-210 | B20: EP-21 | C20: Gestionar los leads en el pipeline comercial | D20: ejecutivo comercial de SIGMA | E20: registrar un lead con su país e identificador y llevarlo por etapas hasta concretarlo | F20: no perder el seguimiento de ningún prospecto y saber cuánto hay en cada etapa | G20: Web | H20: 90 | I20: 8 | J20: Alta | K20: HU-190 | L20: 3 | M20: Terminada | N20: Bryan Chávez | O20: =IF($M20="Terminada",$I20,0) | P20: Centro Comercial V2 (menú Comercial): Resumen, Pipeline, Clientes y Suscripciones, con cajones laterales. Ciclo probado de punta a punta con Hamburgo SA.
A21: HU-211 | B21: EP-21 | C21: Enviar la propuesta y generar el contrato | D21: ejecutivo comercial de SIGMA | E21: armar una propuesta con plan estándar o personalizado y generar el contrato desde ella | F21: que el cliente reciba una oferta clara y firmable, con sus versiones guardadas | G21: Web | H21: 90 | I21: 8 | J21: Alta | K21: HU-210, HU-190 | L21: 3 | M21: Terminada | N21: Bryan Chávez | O21: =IF($M21="Terminada",$I21,0) | P21: Propuesta con Básico/Medio/Full o plan personalizado, implementación, descuento y vigencia; el contrato congela los números de la propuesta.
A22: HU-212 | B22: EP-21 | C22: Firmar el contrato en línea | D22: representante del cliente | E22: leer el contrato y firmarlo desde el enlace que recibí por correo, sin crear una cuenta | F22: dejar la contratación cerrada con respaldo legal sin trámites presenciales | G22: Web | H22: 90 | I22: 5 | J22: Alta | K22: HU-211 | L22: 3 | M22: Terminada | N22: Bryan Chávez | O22: =IF($M22="Terminada",$I22,0) | P22: Firma.aspx es pública; el enlace es de un solo uso por contrato, con hash SHA-256 y registro de fecha e IP.
A23: HU-213 | B23: EP-21 | C23: Cobrar la suscripción con Webpay o transferencia | D23: administrador de SIGMA | E23: emitir cada período de cobro y registrar su pago por Webpay o por transferencia verificada | F23: saber qué cliente está al día y no perder ningún cobro | G23: Web | H23: 90 | I23: 8 | J23: Alta | K23: HU-191, HU-212 | L23: 4 | M23: Terminada | N23: Bryan Chávez | O23: =IF($M23="Terminada",$I23,0) | P23: Chile: UF a pesos del día (Webpay Plus o transferencia nacional). Exterior: USD por transferencia internacional. Mi suscripción (Renovar.aspx) y Pagar.aspx para el cliente.
A24: HU-214 | B24: EP-21 | C24: Atender clientes de otros países | D24: administrador de SIGMA | E24: registrar empresas de Chile, Argentina, Colombia, Ecuador, México y Perú con su identificador, zona horaria y moneda | F24: vender SIGMA fuera de Chile sin cambiar el sistema | G24: Web | H24: 75 | I24: 5 | J24: Media | K24: HU-210 | L24: 2 | M24: Terminada | N24: Bryan Chávez | O24: =IF($M24="Terminada",$I24,0) | P24: Moneda: Chile en UF cobrado en pesos; el resto en USD. El nombre del identificador y su validación dependen del país.
A25: HU-215 | B25: EP-21 | C25: Ejecutar los procesos automáticos de SIGMA | D25: administrador de SIGMA | E25: que ocurrencias, órdenes automáticas, cobros, alertas, UF y vencimiento de demos corran solos cada cierto tiempo | F25: no depender de que alguien abra la web ni de un servidor con agendador | G25: Web (infraestructura) | H25: 90 | I25: 8 | J25: Alta | K25: HU-094, HU-111 | L25: 4 | M25: Terminada | N25: Bryan Chávez | O25: =IF($M25="Terminada",$I25,0) | P25: Planificador interno (Timer en Global.asax) más Jobs.aspx con clave; GitHub Actions lo despierta cada 5 minutos (jobs-sigma.yml). Hospedaje sin SQL Agent ni cron.
A26: HU-216 | B26: EP-21 | C26: Enviar los correos con reintentos y copia de monitoreo | D26: administrador de SIGMA | E26: que todo correo del sistema pase por una cola con reintentos y que yo reciba copia oculta | F26: que un fallo del servidor de correo no pierda mensajes y poder vigilar lo que se envía | G26: Web (infraestructura) | H26: 80 | I26: 5 | J26: Media | K26: HU-215 | L26: 2 | M26: Terminada | N26: Bryan Chávez | O26: =IF($M26="Terminada",$I26,0) | P26: Correo_Cola: se envía de inmediato; si falla, el job CORREOS_COLA reintenta hasta 5 veces. CorreoMonitorearA agrega copia oculta sin cambiar los destinatarios reales.
A27: HU-217 | B27: EP-21 | C27: Reportar un problema y consultar la ayuda de la pantalla | D27: usuario de SIGMA | E27: reportar un problema desde cualquier pantalla y leer la ayuda contextual de esa pantalla | F27: resolver mis dudas sin llamar y que soporte reciba el contexto | G27: Web | H27: 85 | I27: 8 | J27: Alta | K27: HU-006 | L27: 3 | M27: Terminada | N27: Bryan Chávez | O27: =IF($M27="Terminada",$I27,0) | P27: Menú Soporte con 13 pantallas (BD/359–365). «Reportar problema» y «? Ayuda» viven en el master. La ticketera es del plan (cupo mensual).
A28: HU-218 | B28: EP-21 | C28: Atender los tickets de soporte con plazos y encuesta | D28: administrador de SIGMA | E28: gestionar los tickets con prioridad, plazo de respuesta (SLA) y encuesta de satisfacción | F28: cumplir lo prometido al cliente y medir la calidad del servicio | G28: Web | H28: 80 | I28: 5 | J28: Media | K28: HU-217 | L28: 2 | M28: Terminada | N28: Bryan Chávez | O28: =IF($M28="Terminada",$I28,0) | P28: Aviso por la campana existente (9 tipos SOPORTE *); job SOPORTE_SLA cada 5 minutos.
A29: HU-219 | B29: EP-21 | C29: Comunicar novedades con campañas segmentadas | D29: administrador de SIGMA | E29: publicar un aviso (banner, modal o tarjeta) a un grupo de usuarios definido por estado, perfil, cliente o planta | F29: informar cambios y novedades solo a quienes les corresponden | G29: Web | H29: 65 | I29: 5 | J29: Media | K29: HU-217 | L29: 2 | M29: Terminada | N29: Bryan Chávez | O29: =IF($M29="Terminada",$I29,0) | P29: FNC_CAMPANA_AUDIENCIA admite es/no es y Y/O; entrega por banner, modal, card y la campana. BD/381–383 corregidos por QUOTED_IDENTIFIER.
A30: HU-220 | B30: EP-06 | C30: Recorrer y operar la bodega en 3D (SIGMA Twin) | D30: bodeguero | E30: ver mis bodegas como un gemelo digital, preparar un picking y contar desde el recorrido | F30: ubicar cada repuesto sin buscar y mantener el inventario exacto | G30: Web | H30: 85 | I30: 8 | J30: Alta | K30: HU-050, HU-059 | L30: 3 | M30: Terminada | N30: Bryan Chávez | O30: =IF($M30="Terminada",$I30,0) | P30: SIGMA Twin: Three.js incluido en Js/three (sin CDN); racks por pasillo con la convención del mapa; picking FEFO/FIFO/LIFO y conteo cíclico (BD/325–336).
A31: HU-221 | B31: EP-18 | C31: Ver mi inicio con accesos, alertas y SIGMA AI | D31: usuario de SIGMA | E31: un inicio con mis accesos directos, mis indicadores, mi turno y lo que requiere mi atención | F31: empezar el día sabiendo qué hacer sin recorrer menús | G31: Web | H31: 80 | I31: 5 | J31: Media | K31: HU-006 | L31: 2 | M31: Terminada | N31: Bryan Chávez | O31: =IF($M31="Terminada",$I31,0) | P31: Default.aspx con WsInicio (BD/377): accesos por persona, widget SIGMA AI con crear OT en 2 clics, OT recientes, hoy en tu turno y requieren tu atención.
C32: Total Sprint 5 | I32: =SUM(I6:I31) | O32: =SUM(O6:O31)

Sheet Sprint 6
A1: Sprint 6 · App móvil, inteligencia y cierre
A2: Del 11-11-2026 al 24-11-2026 · Aplicación móvil completa (reprogramada desde los Sprints 2 a 5 en la Sprint Review 1), SIGMA AI, dashboard, suscripción e importación de datos.
A3: Historias | B3: =COUNTA($A$6:$A$47) | C3: Puntos comprometidos | D3: =SUM($I$6:$I$47) | E3: Puntos completados | F3: =SUM($O$6:$O$47) | G3: Avance | H3: =IFERROR(SUM($O$6:$O$47)/SUM($I$6:$I$47),0) | I3: Terminadas | J3: =COUNTIF($M$6:$M$47,"Terminada") | K3: Bloqueadas | L3: =COUNTIF($M$6:$M$25,"Bloqueada")
A5: ID | B5: Épica | C5: Historia de usuario | D5: Como | E5: Quiero | F5: Para | G5: Plataforma | H5: Valor | I5: Pts | J5: Prioridad | K5: Dependencias | L5: Escenarios | M5: Estado | N5: Responsable | O5: Pts completados | P5: Observaciones
A6: HU-173 | B6: EP-17 | C6: Ver el panel SIGMA AI al ingresar | D6: planificador o jefe de mantenimiento | E6: ver las predicciones activas apenas entro al sistema | F6: enterarme de un problema mientras todavía puedo evitarlo | G6: Web y App | H6: 95 | I6: 8 | J6: Alta | K6: HU-172 | L6: 5 | M6: Por hacer | N6: Emilio Fuentes | O6: =IF($M6="Terminada",$I6,0)
A7: HU-176 | B7: EP-17 | C7: Generar una orden de trabajo desde una predicción | D7: planificador | E7: convertir una predicción en trabajo concreto | F7: que la anticipación sirva para evitar la falla y no solo para saber qué venia | G7: Web | H7: 95 | I7: 5 | J7: Alta | K7: HU-175, HU-110 | L7: 4 | M7: Por hacer | N7: Emilio Fuentes | O7: =IF($M7="Terminada",$I7,0)
A8: HU-175 | B8: EP-17 | C8: Ver por qué el modelo predice lo que predice | D8: jefe de mantenimiento | E8: entender en qué se basa una predicción | F8: poder decidir con fundamento y responder cuando me pregunten de dónde salió | G8: Web y App | H8: 90 | I8: 5 | J8: Alta | K8: HU-173 | L8: 4 | M8: Por hacer | N8: Emilio Fuentes | O8: =IF($M8="Terminada",$I8,0)
A9: HU-180 | B9: EP-18 | C9: Consultar el tablero de indicadores | D9: jefe de mantenimiento | E9: ver en una pantalla el estado del área | F9: tomar decisiones con datos y no con impresiones | G9: Web | H9: 90 | I9: 8 | J9: Alta | K9: HU-120 | L9: 3 | M9: Por hacer | N9: Bryan Chávez | O9: =IF($M9="Terminada",$I9,0)
A10: HU-174 | B10: EP-17 | C10: Recibir el aviso de una predicción crítica | D10: planificador | E10: que una predicción crítica me llame la atención cuando aparece | F10: no descubrirla tres días después revisando un listado | G10: Web y App | H10: 85 | I10: 8 | J10: Alta | K10: HU-173, HU-162 | L10: 7 | M10: Por hacer | N10: Emilio Fuentes | O10: =IF($M10="Terminada",$I10,0)
A11: HU-177 | B11: EP-17 | C11: Registrar si la predicción se cumplió | D11: planificador | E11: registrar qué ocurrió realmente después de una predicción | F11: que el modelo aprenda de sus aciertos y de sus errores | G11: Web | H11: 85 | I11: 5 | J11: Alta | K11: HU-176 | L11: 3 | M11: Por hacer | N11: Emilio Fuentes | O11: =IF($M11="Terminada",$I11,0)
A12: HU-181 | B12: EP-18 | C12: Consultar el cumplimiento del plan de mantenimiento | D12: jefe de mantenimiento | E12: saber qué porcentaje del plan se está cumpliendo | F12: detectar a tiempo si el mantenimiento preventivo se está postergando | G12: Web | H12: 85 | I12: 5 | J12: Alta | K12: HU-086 | L12: 3 | M12: Por hacer | N12: Catalina Pescio | O12: =IF($M12="Terminada",$I12,0)
A13: HU-182 | B13: EP-18 | C13: Consultar disponibilidad y confiabilidad de los equipos | D13: jefe de mantenimiento | E13: saber cuánto estuvo disponible cada equipo y cada cuánto falla | F13: priorizar dónde intervenir con criterio y no por percepción | G13: Web | H13: 85 | I13: 8 | J13: Alta | K13: HU-124 | L13: 3 | M13: Por hacer | N13: Bryan Chávez | O13: =IF($M13="Terminada",$I13,0)
A14: HU-183 | B14: EP-18 | C14: Consultar los costos de mantenimiento | D14: jefe de mantenimiento | E14: saber cuánto costó mantener cada equipo y cada área | F14: sustentar el presupuesto del área con cifras verificables | G14: Web | H14: 85 | I14: 8 | J14: Alta | K14: HU-117 | L14: 3 | M14: Por hacer | N14: Bryan Chávez | O14: =IF($M14="Terminada",$I14,0)
A15: HU-200 | B15: EP-20 | C15: Importar activos desde una planilla | D15: administrador del cliente | E15: cargar el maestro de activos desde la planilla que ya tengo | F15: poner en marcha el sistema sin digitar cientos de equipos | G15: Web | H15: 85 | I15: 13 | J15: Alta | K15: Sin dependencias | L15: 4 | M15: Por hacer | N15: Catalina Pescio | O15: =IF($M15="Terminada",$I15,0)
A16: HU-184 | B16: EP-18 | C16: Consultar la bandeja de alertas | D16: planificador | E16: ver en un solo lugar todo lo que el sistema detectó | F16: no revisar cinco pantallas distintas para saber qué requiere atención | G16: Web y App | H16: 80 | I16: 5 | J16: Media | K16: HU-053, HU-091 | L16: 3 | M16: Por hacer | N16: Catalina Pescio | O16: =IF($M16="Terminada",$I16,0)
A17: HU-201 | B17: EP-20 | C17: Resolver las celdas ambiguas de una importación | D17: administrador del cliente | E17: corregir solo lo que el sistema no pudo interpretar | F17: no volver a digitar la fila completa por un dato mal escrito | G17: Web | H17: 80 | I17: 8 | J17: Media | K17: HU-200 | L17: 4 | M17: Por hacer | N17: Catalina Pescio | O17: =IF($M17="Terminada",$I17,0)
... A25: HU-203 | B25: EP-20 | C25: Consultar el historial de importaciones | D25: administrador del cliente | E25: revisar qué cargas se hicieron y con qué resultado | F25: poder rastrear de dónde salió un registro cuando algo no cuadra | G25: Web | H25: 55 | I25: 3 | J25: Baja | K25: HU-200 | L25: 2 | M25: Por hacer | N25: Catalina Pescio | O25: =IF($M25="Terminada",$I25,0)
A26: HU-150 | B26: EP-15 | C26: Sincronizar los datos hacia el dispositivo | D26: técnico de mantenimiento | E26: descargar al teléfono lo que voy a necesitar en terreno | F26: poder trabajar después sin depender de la señal | G26: App | H26: 95 | I26: 13 | J26: Alta | K26: HU-035 | L26: 3 | M26: Por hacer | N26: Bryan Chávez | O26: =IF($M26="Terminada",$I26,0) | P26: Reprogramada desde el Sprint 2 al Sprint 6 por el cliente en la Sprint Review 1 (15-09-2026): la app móvil se entrega cuando la configuración base en la web esté hecha.
