Workbook

Sheet Resumen
B6: Evidencia de Daily Scrum
B7: SIGMA — Sistema Integrado de Gestión de Mantenimiento Industrial
B8: Bitácora de avance, impedimentos y próximos pasos · Equipo Código Creativo
B10: Ficha del artefacto
B11: Evento Scrum | C11: Daily Scrum · quince minutos, misma hora y mismo lugar
B12: Periodicidad | C12: Todos los días hábiles del Sprint
B13: Participantes | C13: Equipo completo: Bryan Chávez, Catalina Pescio, Emilio Fuentes
B14: Facilita | C14: Emilio Fuentes (Scrum Master)
B15: Cobertura | C15: Sprints 1 a 6 · del 02-09-2026 al 24-11-2026 · semanas académicas S5 a S17
B16: Formato de entrega | C16: Bitácora en Excel, compatible con el tablero de GitHub Projects
B17: Versión | C17: 1.3 · 12-10-2026 · Sprints 1 a 5 con registro diario; HU-142 y HU-143 de Catalina En revisión
B19: Indicadores de la bitácora
B20: Dailies planificados | C20: Participaciones esperadas | D20: Participaciones registradas | E20: Cumplimiento | F20: Impedimentos registrados | G20: Impedimentos abiertos | H20: Impedimentos resueltos
B21: =58 | C21: =COUNTA(Bitácora!$A$5:$A$181) | D21: =COUNTIF(Bitácora!$P$5:$P$181,"Sí") | E21: =IFERROR(COUNTIF(Bitácora!$P$5:$P$181,"Sí")/COUNTA(Bitácora!$A$5:$A$181),0) | F21: =COUNTA(Impedimentos!$B$5:$B$64) | G21: =COUNTIF(Impedimentos!$J$5:$J$64,"Abierto")+COUNTIF(Impedimentos!$J$5:$J$64,"En gestión")+COUNTIF(Impedimentos!$J$5:$J$64,"Escalado") | H21: =COUNTIF(Impedimentos!$J$5:$J$64,"Resuelto")
B23: Detalle por Sprint
B24: Sprint | C24: Foco | D24: Desde | E24: Hasta | F24: Dailies | G24: Participaciones registradas | H24: Cumplimiento | I24: Impedimentos
B25: Sprint 1 | C25: Fundaciones | D25: 46267 | E25: 46280 | F25: 10 | G25: =COUNTIFS(Bitácora!$F$5:$F$181,$B25,Bitácora!$P$5:$P$181,"Sí") | H25: =IFERROR($G25/COUNTIF(Bitácora!$F$5:$F$181,$B25),0) | I25: =COUNTIF(Impedimentos!$C$5:$C$64,$B25)
B26: Sprint 2 | C26: Activos | D26: 46281 | E26: 46294 | F26: 9 | G26: =COUNTIFS(Bitácora!$F$5:$F$181,$B26,Bitácora!$P$5:$P$181,"Sí") | H26: =IFERROR($G26/COUNTIF(Bitácora!$F$5:$F$181,$B26),0) | I26: =COUNTIF(Impedimentos!$C$5:$C$64,$B26)
B27: Sprint 3 | C27: Recursos y recurrencia | D27: 46295 | E27: 46308 | F27: 9 | G27: =COUNTIFS(Bitácora!$F$5:$F$181,$B27,Bitácora!$P$5:$P$181,"Sí") | H27: =IFERROR($G27/COUNTIF(Bitácora!$F$5:$F$181,$B27),0) | I27: =COUNTIF(Impedimentos!$C$5:$C$64,$B27)
B28: Sprint 4 | C28: Trabajo planificado | D28: 46309 | E28: 46322 | F28: 10 | G28: =COUNTIFS(Bitácora!$F$5:$F$181,$B28,Bitácora!$P$5:$P$181,"Sí") | H28: =IFERROR($G28/COUNTIF(Bitácora!$F$5:$F$181,$B28),0) | I28: =COUNTIF(Impedimentos!$C$5:$C$64,$B28)
B29: Sprint 5 | C29: Ejecución | D29: 46323 | E29: 46336 | F29: 10 | G29: =COUNTIFS(Bitácora!$F$5:$F$181,$B29,Bitácora!$P$5:$P$181,"Sí") | H29: =IFERROR($G29/COUNTIF(Bitácora!$F$5:$F$181,$B29),0) | I29: =COUNTIF(Impedimentos!$C$5:$C$64,$B29)
B30: Sprint 6 | C30: Inteligencia y cierre | D30: 46337 | E30: 46350 | F30: 10 | G30: =COUNTIFS(Bitácora!$F$5:$F$181,$B30,Bitácora!$P$5:$P$181,"Sí") | H30: =IFERROR($G30/COUNTIF(Bitácora!$F$5:$F$181,$B30),0) | I30: =COUNTIF(Impedimentos!$C$5:$C$64,$B30)
B31: Total | F31: =SUM(F25:F30) | G31: =SUM(G25:G30) | H31: =IFERROR(G31/COUNTA(Bitácora!$A$5:$A$181),0) | I31: =SUM(I25:I30)
B33: Días sin Daily por feriado
B34: Fecha | C34: Feriado | D34: Sprint afectado
B35: 46283 | C35: Independencia Nacional | D35: Sprint 2
B36: 46307 | C36: Encuentro de Dos Mundos | D36: Sprint 3
B38: El 19 de septiembre y el 31 de octubre de 2026 caen sábado, y el 1 de noviembre domingo: no reducen días hábiles del Sprint.
B40: Por qué el registro va por delante del calendario
B41: Dejamos constancia de algo que se ve en las fechas: vamos adelantados respecto del calendario. SIGMA son 785 puntos, 138 historias y 20 épicas para un equipo de tres, y la única forma de absorber ese alcance fue adelantar construcción: lo que aquí se registra en la ventana del Sprint 4 y del Sprint 5 quedó construido y verificado contra la base entre el 11 y el 14 de septiembre. El registro mantiene el calendario planificado para no romper la trazabilidad con el Sprint Backlog, el burndown y los informes de prueba. Los Sprints 1 a 3 están cerrados y verificados con evidencia; del Sprint 4 se entregaron 9 de 24 historias y del Sprint 5, 8 de 26. El Sprint 6 no tiene registro diario todavía porque ninguna de sus historias está Terminada: se llenará cuando se ejecute.

Sheet Bitácora
A1: Bitácora de Daily Scrum
A2: Registro breve y periódico del avance, los impedimentos y los próximos pasos. Se completa en los quince minutos del Daily, no después.
A4: N.º | B4: Fecha | C4: Día | D4: Integrante | E4: Rol | F4: Sprint | G4: Sem. Sprint | H4: Sem. acad. | I4: Qué hice desde el último Daily | J4: Qué haré hasta el próximo Daily | K4: Impedimentos | L4: Historia | M4: Tarea | N4: Estado en GitHub Projects | O4: Issue / PR | P4: Realizado | Q4: Acuerdo del equipo y próximos pasos
A5: 0 | B5: 46264 | C5: domingo | D5: Bryan Chávez | E5: Developer | F5: Sprint 1 | G5: Previa | H5: S4 | I5: Construí la API REST de SIGMA sobre el proyecto Solucion/SIGMA/API: 14 controllers con los endpoints de las 17 historias del Sprint 1 (sesión, permisos, clientes, plantas, áreas, centros de costo, usuarios, perfiles, grupos, especialidades, permisos puntuales, catálogos, recuperación y mi perfil). Antes construí la base transversal: ErrorSql, que traduce cada RAISERROR de un SP a su código HTTP; ApiBase, con la validación y el 404; Datos, el mapeador a DTO que resuelve el NULL una sola vez; Pagina; CacheCorta; y el token JWT con el usuario y el cliente adentro. Compila en exitcode=0. | J5: Levantar la API en IIS y ejercitar los endpoints de punta a punta contra la base: hoy solo está verificado que compila. Empezar por POST /sesion, que es de donde salen los tokens del resto. | L5: HU-001, HU-002, HU-003, HU-006, HU-010 a HU-017, HU-020, HU-021 | M5: T-1006, T-1017, T-1030, T-1032, T-1046, T-1059, T-1061, T-1076, T-1078, T-1092, T-1094, T-1107, T-1120, T-1122, T-1136, T-1138, T-1152, T-1154, T-1168, T-1170, T-1183, T-1195, T-1197, T-1211, T-1213, T-1226, T-1228, T-1240 | N5: In Review | P5: Sí | Q5: Trabajo de PREPARACIÓN, anterior al inicio formal del Sprint 1 (02-09). Se registra con semana "Previa" para no falsear las fechas. Acuerdo: la API queda construida y compilando; probarla y documentarla es lo siguiente, y sin eso ninguna historia pasa de "En revisión".
A6: 0 | B6: 46264 | C6: domingo | D6: Emilio Fuentes | E6: Scrum Master | F6: Sprint 1 | G6: Previa | H6: S4 | I6: Definí con Bryan el manejo de errores de los SPs, que era la tarea que se repetía en cuatro historias: severidad 16 es una regla de negocio y el texto decide el código (409 si ya existe, 423 si está bloqueada, 403, 404, 400); cualquier otra cosa es 500 y su detalle NO viaja al cliente, queda en el log. También la caché corta de 60 segundos para permisos y catálogos, y los DTO de salida para que no se filtren hash, sal ni columnas de auditoría. | J6: Revisar con Catalina el orden de las pruebas del sprint, partiendo por HU-001 y HU-006, que son de las que dependen las demás. | K6: SMTP sigue sin configurar: HU-004 queda bloqueada. El token de recuperación se genera y se guarda, pero el correo no sale. | L6: HU-001, HU-002, HU-003, HU-004, HU-006, HU-011 a HU-017, HU-020, HU-021 | M6: T-1007, T-1018, T-1031, T-1033, T-1047, T-1060, T-1062, T-1077, T-1079, T-1093, T-1095, T-1108, T-1121, T-1123, T-1137, T-1139, T-1153, T-1155, T-1169, T-1171, T-1184, T-1196, T-1198, T-1212, T-1214, T-1227, T-1239 | N6: In Review | P6: Sí | Q6: Trabajo de PREPARACIÓN, anterior al inicio formal del Sprint 1 (02-09). Se registra con semana "Previa" para no falsear las fechas. Acuerdo: la API queda construida y compilando; probarla y documentarla es lo siguiente, y sin eso ninguna historia pasa de "En revisión".
A7: 0 | B7: 46264 | C7: domingo | D7: Catalina Pescio | E7: Product Owner | F7: Sprint 1 | G7: Previa | H7: S4 | I7: Revisé que los endpoints respondan a lo que piden las historias. Levanté una desviación en T-1226: la tarea pedía un alta idempotente por uuid para "mi perfil", pero mi perfil no se crea, se edita, así que no hay alta ni uuid que repetir. Se acordó entregar PUT /mi-perfil y POST /mi-perfil/password, que es lo que HU-005 realmente necesita, y dejar la desviación anotada en la tarea. | J7: Escribir y ejecutar un caso de prueba por cada criterio de aceptación de las 17 historias, y documentar los endpoints. Son las 34 tareas de Pruebas y Documentación del sprint, todas pendientes: nada de lo construido está probado todavía. | L7: Las 17 historias del Sprint 1 | M7: T-1011, T-1012 y las demás de Pruebas y Documentación | N7: Todo | P7: Sí | Q7: Trabajo de PREPARACIÓN, anterior al inicio formal del Sprint 1 (02-09). Se registra con semana "Previa" para no falsear las fechas. Acuerdo: la API queda construida y compilando; probarla y documentarla es lo siguiente, y sin eso ninguna historia pasa de "En revisión".
A8: 0 | B8: 46266 | C8: martes | D8: Bryan Chávez | E8: Developer | F8: Sprint 3 | G8: Previa | H8: S4 | I8: Me enfrenté a cinco frentes. Primero creé el módulo de INVENTARIO: el maestro de repuestos, la bodega y sus ubicaciones, el control de los movimientos con su trazabilidad completa, el saldo por ubicación, y le incorporé una carga masiva desde Excel para hacerle más ágil la carga de datos al bodeguero. Junto a Emilio incorporamos también el código automático, que quedó aplicado en ese módulo. Después incorporé las ALERTAS: detección continua, consulta, severidad según el quiebre de la alerta, el panel de la campana, y creé una bandeja de entrada para tener esa información a modo histórico. También completé el módulo de TERCEROS, que contempla la creación de proveedores y el permiso de trabajo con la vigencia de los trabajadores. De la mano de eso incorporé Azure Blob Storage para almacenar la documentación de los permisos de trabajo: hicimos ese ajuste para no guardarla directo en la base de datos. Y hoy avancé la PROGRAMACIÓN del mantenimiento: dejé la base —23 procedimientos, la función que proyecta las fechas y las dos pantallas, compilando— más el bloque de procedimientos que estaba escrito y sin aplicar. Al cierre arreglé el error que dejó master sin compilar. Todo esto está en el Excel del Sprint 3 como terminado en web y API; le faltan la documentación y las pruebas. | J8: Me quedo con las historias del módulo de programaciones: HU-070, HU-071, HU-072 y HU-075. Son cortas y van todas por lo mismo. Figuran como terminadas, pero las voy a revisar bien igual antes de darlas por cerradas. Voy a dejar la base de la programación sin ir más allá hasta que cerremos bien el otro sprint. Aparte abro el PR que desbloquea master, que hoy no compila, y saco del repositorio las carpetas de salida de compilación. | K8: Estoy un poco parado en programación: hay tareas que son del Sprint 4 que me tienen amarrado en el Sprint 3. No puedo generar ninguna ocurrencia del plan de mantenimiento, porque el plan es del Sprint 4 y nosotros estamos en el 3. Y tenía otro que dependía del Sprint 2: la historia HU-074, la del activo variable; esa tabla no tenía ningún registro, así que no pude hacer una prueba eficiente. Hay un tercero que quedó planteado y sin resolver: el medidor está amarrado a un solo horómetro y el criterio de HU-073 pide que cuatro equipos iguales disparen cada uno con el suyo. Los tres están en la hoja de Impedimentos, N.º 6 a 8. | L8: HU-050 a HU-060, HU-063, HU-064, HU-070 a HU-072, HU-075, HU-077 · toma HU-070, HU-071, HU-072 y HU-075 | M8: T-3201 a T-3205, T-3231 a T-3241, T-3042 a T-3052, T-3244 a T-3254, T-3016 a T-3027, T-3257 a T-3267, T-3113 a T-3126, T-3956, y las nuevas T-3960 a T-3971 | N8: In Review | O8: Rama fix/clases-duplicadas-activo · PR pendiente de abrir | P8: Sí | Q8: ACUERDO: las tareas quedan definidas en esta Daily. Emilio termina el Sprint 2 en web, base de datos y API —queda pendiente la app— y pasa a apoyar el Sprint 3 tomando HU-061 y HU-062, las dos de procedimientos, porque una depende de la otra. Bryan sigue con el módulo de programaciones: HU-070, HU-071, HU-072 y HU-075, dejando la base sin avanzar más hasta cerrar bien el sprint anterior. Catalina sigue con las pruebas: cierra el Sprint 1 con todo documentado, incluida la de la cuenta deshabilitada que ya puede crear, y de ahí pasa al Sprint 2. HU-151, trabajar sin conexión, QUEDA SIN ASIGNACIÓN: hay que analizarla antes, porque no está claro si se crea la tabla de sincronización o si va por SQLite en el teléfono; se acordó retomarla cuando se empiece con la aplicación móvil, ya que solo tiene tareas de base de datos, API y móvil. Se acordó también REVISAR lo que figura como terminado antes de darlo por cerrado, tanto en programaciones como en la base de datos de HU-061. NO SE RESOLVIERON las tres decisiones de modelo de los impedimentos N.º 6, 7 y 8, ni el estado de las cuatro historias construidas que siguen en "Por hacer" (HU-051, HU-060, HU-063, HU-064). Nota de calendario: es trabajo de PREPARACIÓN, por delante del inicio formal del Sprint 1 (02-09); se registra con semana "Previa", igual que el 30-08.
A9: 0 | B9: 46266 | C9: martes | D9: Emilio Fuentes | E9: Scrum Master | F9: Sprint 3 | G9: Previa | H9: S4 | I9: Logré completar nuevas historias. Arranqué con la HU-035, el registro de un activo: se puede dar de alta un equipo con su ficha técnica completa y el código se genera automático, para que no haya problema con las demás historias que también tienen que generarlo. Seguí con la HU-042, que configura el medidor de un activo —el horómetro o contador de horas—, con la idea de poder programar mantenimientos por uso y no solo por calendario. Después fui a los catálogos que describen el activo: la HU-030, tipo de activo, que quedó con un árbol de jerarquía de tipos y subtipos; la HU-031, modelos de activo, donde ya se distinguen los modelos globales de la plataforma de los propios de cada cliente, y me aseguré al dar de baja de que no queden datos colgados; y la HU-032, los atributos técnicos que definen qué datos describe cada tipo de activo, por ejemplo la potencia, el voltaje o el porcentaje. También cerré la HU-036, los componentes, que son las piezas que forman cada activo con su jerarquía de componente superior, y la HU-040, las unidades de medida: kilovatios, voltios, litros por minuto y varias más que se pueden ir agregando. Esas siete están construidas y compilan bien, y las dejé anotadas en revisión en el Excel, porque faltan las pruebas de navegación. Me quedan dos en curso, la HU-037 —ficha e historial de activos— y la HU-038 —cambio de estado de un activo con su motivo—: la parte web ya está terminada y falta solo el consumo desde la app. Todo quedó subido a mi rama, que ya está conversando con master. | J9: Del Sprint 2 estaría totalmente finalizado lo que es web, base de datos y API; queda pendiente la aplicación móvil y ya estaría listo para entregar al equipo de QA. Como Catalina va a seguir con las pruebas, yo paso a prestar apoyo en las tareas del Sprint 3: tomo la HU-061, administrar procedimientos reutilizables, y la HU-062, definir los pasos de un procedimiento, que dependen una de la otra. Cualquier duda le comunico a Bryan. Antes de avanzar voy a revisar qué está realmente creado, porque figura una parte como terminada y no está confirmado. | K9: Se ajustaron cosas de forma: el orden de los botones, el orden de los input, las palabras, y a la fecha se le agregó un calendario. El problema principal que tuve fue el de los códigos: al anotar un código uno podía poner cualquier número o letra, así que se automatizó y ahora se genera solo con las iniciales de cada módulo. Aparte, mi rama de HU-031 y la de Alertas/Terceros definieron las mismas clases y al mergear el PR #35 master dejó de compilar; ya está resuelto en una rama y falta mergear. | L9: En revisión: HU-030, HU-031, HU-032, HU-035, HU-036, HU-040, HU-042 · En curso: HU-037, HU-038 · toma HU-061 y HU-062 | N9: In Review | P9: Sí
A10: 0 | B10: 46266 | C10: martes | D10: Catalina Pescio | E10: Product Owner | F10: Sprint 3 | G10: Previa | H10: S4 | I10: Realicé la sincronización de mi branch, por el cambio de nombre. Ejecuté las pruebas de los diferentes casos según los criterios de aceptación que se habían previsto, y realicé también un informe de las pruebas que queda guardado como evidencia, en un archivo MD. Eso es del Sprint 1. Quedó pendiente el tercer criterio, porque no tenía una cuenta deshabilitada para realizar la prueba. También instalé Swagger en la carpeta de la API para poder hacer las pruebas; solo quedó pendiente verlo funcionando. | J10: Cerrar ya el Sprint 1, con todas las pruebas completas y documentadas, y ver los avances de mis tareas del Sprint 2. Me falta la prueba de la cuenta deshabilitada y ya me dijeron que la puedo crear. | K10: Solamente la del usuario: no tenía una cuenta deshabilitada para probar el tercer criterio de aceptación. Y un error en la instalación del Swagger, que me hizo tomar un poco más de tiempo; queda pendiente verlo funcionando. | L10: Las 17 historias del Sprint 1 · pasa a las pruebas del Sprint 2 | N10: In Review | P10: Sí
A11: 1 | B11: 46267 | C11: miércoles | D11: Bryan Chávez | E11: Developer | F11: Sprint 1 | G11: Semana 1 | H11: S5 | I11: Levanté la base SIGMA en el servidor y corrí los scripts del modelo de seguridad. Escribí SEL_USUARIO_LOGIN y la validación de la contraseña con hash. | J11: Cerrar POST /api/auth/login y que el token baje con los permisos del usuario adentro. | K11: Ninguno. | L11: HU-001, HU-006 | M11: T-1001, T-1004, T-1006, T-1008 a T-1010, T-1014, T-1017, T-1901, T-1903, T-1905 a T-1906 | N11: In Progress | P11: Sí
A12: 1 | B12: 46267 | C12: miércoles | D12: Catalina Pescio | E12: Product Owner | F12: Sprint 1 | G12: Semana 1 | H12: S5 | I12: Leí las 17 historias comprometidas y anoté los criterios de aceptación que están escritos de forma ambigua, sobre todo los de permisos. | J12: Escribir la matriz de casos de prueba de HU-001 y HU-006, un caso por criterio. | K12: Ninguno. | L12: HU-001, HU-006 | M12: T-1003, T-1011 a T-1013, T-1016, T-1022 a T-1023 | N12: Todo | P12: Sí
A13: 1 | B13: 46267 | C13: miércoles | D13: Emilio Fuentes | E13: Scrum Master | F13: Sprint 1 | G13: Semana 1 | H13: S5 | I13: Armé el tablero en GitHub Projects con las 17 historias del Sprint 1 y las columnas Todo, In Progress, In Review, Done y Blocked. Repasé con Bryan el patrón de páginas ASP. | J13: Construir Login.aspx contra el endpoint de Bryan y dejar el menú lateral leyendo desde Menus. | K13: Ninguno. | L13: HU-001, HU-006 | M13: T-1002, T-1005, T-1007, T-1015, T-1018 a T-1021, T-1902, T-1904 | N13: In Progress | P13: Sí | Q13: Se define el ritmo del Sprint: Daily a las 19:00 por Meet, quince minutos. Bryan toma el motor de datos y la API, Emilio las pantallas de seguridad y Catalina las pruebas y la documentación. Nada entra a master sin pull request.
A14: 2 | B14: 46268 | C14: jueves | D14: Bryan Chávez | E14: Developer | F14: Sprint 1 | G14: Semana 1 | H14: S5 | I14: Terminé el login: el endpoint entrega el token y Token.PuedeVer ya filtra el menú. Empecé los SP del maestro de usuarios. | J14: Dejar INS, UPD y DEL_USUARIO dentro de transacción, con la validación de correo duplicado. | K14: Ninguno. | L14: HU-001, HU-014 | M14: T-1001, T-1004, T-1006, T-1008 a T-1010, T-1024, T-1027, T-1030, T-1032, T-1034, T-1036 a T-1037, T-1906 | N14: In Review | O14: #12 | P14: Sí
A15: 2 | B15: 46268 | C15: jueves | D15: Catalina Pescio | E15: Product Owner | F15: Sprint 1 | G15: Semana 1 | H15: S5 | I15: Ejecuté los casos de HU-001. Encontré que la cuenta deshabilitada entraba igual: el SP no revisaba el estado. | J15: Reejecutar HU-001 con el arreglo y empezar los casos de HU-002. | K15: La base no tenía ninguna cuenta deshabilitada para probar el criterio 3; la creé yo. | L15: HU-001, HU-002 | M15: T-1003, T-1011 a T-1012, T-1043, T-1051 a T-1052 | N15: In Review | P15: Sí
A16: 2 | B16: 46268 | C16: jueves | D16: Emilio Fuentes | E16: Scrum Master | F16: Sprint 1 | G16: Semana 1 | H16: S5 | I16: Dejé andando Login.aspx y la selección de cliente cuando el usuario pertenece a más de uno: el combo aparece solo si hay más de una opción. | J16: Montar el listado Usuarios.aspx con la ficha en RadWindow. | K16: Ninguno. | L16: HU-002, HU-014 | M16: T-1025, T-1028, T-1031, T-1033, T-1035, T-1042, T-1045, T-1047 a T-1048, T-1050 | N16: In Progress | P16: Sí | Q16: Se acuerda que ninguna pantalla se da por terminada sin su fila en Menus: sin esa fila el permiso no existe y la página queda fuera del control de acceso.
A17: 3 | B17: 46269 | C17: viernes | D17: Bryan Chávez | E17: Developer | F17: Sprint 1 | G17: Semana 1 | H17: S5 | I17: Escribí los SP de perfiles y de la tabla puente Perfil_Menu, con la regla de que un perfil sin ningún permiso no se puede guardar. | J17: Exponer los endpoints de perfiles y armar el árbol de permisos desde el servidor. | K17: Ninguno. | L17: HU-015 | M17: T-1054, T-1057, T-1059, T-1061, T-1063, T-1065 a T-1066 | N17: In Progress | P17: Sí
A18: 3 | B18: 46269 | C18: viernes | D18: Catalina Pescio | E18: Product Owner | F18: Sprint 1 | G18: Semana 1 | H18: S5 | I18: Documenté en Swagger los endpoints de login y de usuarios, y dejé escritos los casos de HU-014. | J18: Probar HU-014 de punta a punta, incluida la validación de correo repetido. | K18: Ninguno. | L18: HU-014, HU-015 | M18: T-1026, T-1029, T-1038 a T-1040, T-1053, T-1056, T-1067 a T-1069 | N18: In Progress | P18: Sí
A19: 3 | B19: 46269 | C19: viernes | D19: Emilio Fuentes | E19: Scrum Master | F19: Sprint 1 | G19: Semana 1 | H19: S5 | I19: Armé la pantalla de perfiles con el árbol de menús y una casilla por permiso. | J19: Terminar el guardado del árbol y registrar Perfiles.aspx en Menus. | K19: El RadTreeView pierde las marcas en el postback; lo estoy resolviendo con ViewState. | L19: HU-015 | M19: T-1055, T-1058, T-1060, T-1062, T-1064 | N19: In Progress | P19: Sí | Q19: Perfiles y permisos queda como la historia más pesada del Sprint: se le dan dos días completos y nadie más toca esas tablas mientras tanto.
A20: 4 | B20: 46272 | C20: lunes | D20: Bryan Chávez | E20: Developer | F20: Sprint 1 | G20: Semana 1 | H20: S6 | I20: Cerré perfiles y pasé a la organización: SP de plantas y de áreas, con la jerarquía de área padre e hija. | J20: Dejar los endpoints de plantas y áreas, y el filtro de áreas por planta. | K20: Ninguno. | L20: HU-015, HU-011, HU-012 | M20: T-1054, T-1057, T-1059, T-1061, T-1063, T-1065 a T-1066, T-1071, T-1074, T-1076, T-1078, T-1081, T-1087, T-1090, T-1092, T-1094, T-1096, T-1098 a T-1099 | N20: In Review | O20: #18 | P20: Sí
A21: 4 | B21: 46272 | C21: lunes | D21: Catalina Pescio | E21: Product Owner | F21: Sprint 1 | G21: Semana 1 | H21: S6 | I21: Probé HU-015 completa: el perfil sin permisos ya no se guarda y el usuario ve solo lo que le corresponde. | J21: Escribir los casos de plantas y áreas, con foco en el borrado lógico de un área que tiene hijas. | K21: Ninguno. | L21: HU-015, HU-011, HU-012 | M21: T-1053, T-1056, T-1067 a T-1070, T-1073, T-1084 a T-1086, T-1089, T-1100 a T-1101 | N21: In Review | P21: Sí
A22: 4 | B22: 46272 | C22: lunes | D22: Emilio Fuentes | E22: Scrum Master | F22: Sprint 1 | G22: Semana 1 | H22: S6 | I22: Terminé el árbol de permisos y lo registré en Menus. Empecé Plantas.aspx con el mapa de Google. | J22: Terminar el mapa de la planta y montar Areas.aspx colgando de la planta seleccionada. | K22: No está confirmado que la clave de Google Maps tenga restricción de dominio. | L22: HU-015, HU-011 | M22: T-1055, T-1058, T-1060, T-1062, T-1064, T-1072, T-1075, T-1077, T-1079 a T-1080, T-1082 a T-1083 | N22: In Progress | P22: Sí
A23: 5 | B23: 46273 | C23: martes | D23: Bryan Chávez | E23: Developer | F23: Sprint 1 | G23: Semana 1 | H23: S6 | I23: Dejé listos los SP del cierre de sesión con expiración por inactividad y los del maestro de clientes. | J23: Terminar el endpoint de logout y revisar que todos los SEL filtren por cliente. | K23: Ninguno. | L23: HU-003, HU-010 | M23: T-1103, T-1106 a T-1107, T-1116, T-1119 a T-1120, T-1122, T-1124, T-1126 a T-1127 | N23: In Progress | P23: Sí
A24: 5 | B24: 46273 | C24: martes | D24: Catalina Pescio | E24: Product Owner | F24: Sprint 1 | G24: Semana 1 | H24: S6 | I24: Ejecuté los casos de plantas y áreas. El área con hijas se dejaba deshabilitar sin avisar; quedó reportado. | J24: Probar el cierre de sesión y la expiración por inactividad. | K24: Ninguno. | L24: HU-011, HU-012, HU-003 | M24: T-1070, T-1073, T-1084 a T-1086, T-1089, T-1100 a T-1102, T-1105, T-1112 a T-1113 | N24: In Review | P24: Sí
A25: 5 | B25: 46273 | C25: martes | D25: Emilio Fuentes | E25: Scrum Master | F25: Sprint 1 | G25: Semana 1 | H25: S6 | I25: Terminé plantas y áreas, las dos registradas en Menus con su permiso. Empecé Clientes.aspx. | J25: Cerrar la ficha del cliente y dejar la sesión expirando a los treinta minutos en el lado web. | K25: Ninguno. | L25: HU-011, HU-012, HU-010 | M25: T-1072, T-1075, T-1077, T-1079 a T-1080, T-1082 a T-1083, T-1088, T-1091, T-1093, T-1095, T-1097, T-1114, T-1117, T-1121, T-1123, T-1125 | N25: In Review | O25: #21 | P25: Sí | Q25: Se confirma que todo borrado del sistema es lógico: se marca deshabilitado y se rechaza con mensaje si el registro está en uso.
A26: 6 | B26: 46274 | C26: miércoles | D26: Bryan Chávez | E26: Developer | F26: Sprint 1 | G26: Semana 2 | H26: S6 | I26: Escribí los SP de especialidades y certificaciones del usuario, y el del permiso puntual con su fecha de vigencia. | J26: Dejar el endpoint del permiso puntual y que Token.Puede lo sume al permiso del perfil. | K26: Ninguno. | L26: HU-017, HU-007 | M26: T-1132, T-1135 a T-1136, T-1138, T-1141, T-1148, T-1151 a T-1152, T-1154, T-1156, T-1158 a T-1159 | N26: In Progress | P26: Sí
A27: 6 | B27: 46274 | C27: miércoles | D27: Catalina Pescio | E27: Product Owner | F27: Sprint 1 | G27: Semana 2 | H27: S6 | I27: Documenté clientes, plantas y áreas en Swagger y actualicé el MD de estado. | J27: Escribir los casos de HU-007: que el permiso puntual sume y que caduque solo. | K27: Ninguno. | L27: HU-010, HU-011, HU-007 | M27: T-1070, T-1073, T-1084 a T-1085, T-1115, T-1118, T-1128 a T-1129, T-1147, T-1150, T-1160 a T-1161 | N27: In Progress | P27: Sí
A28: 6 | B28: 46274 | C28: miércoles | D28: Emilio Fuentes | E28: Scrum Master | F28: Sprint 1 | G28: Semana 2 | H28: S6 | I28: Cerré clientes. Monté la pestaña de especialidades dentro de la ficha del usuario. | J28: Armar la pantalla del permiso puntual y probar que convive con el permiso del perfil. | K28: Ninguno. | L28: HU-010, HU-017 | M28: T-1114, T-1117, T-1121, T-1123, T-1125, T-1130, T-1133, T-1137, T-1139 a T-1140, T-1142 a T-1143 | N28: In Progress | P28: Sí
A29: 7 | B29: 46275 | C29: jueves | D29: Bryan Chávez | E29: Developer | F29: Sprint 1 | G29: Semana 2 | H29: S6 | I29: Terminé el permiso puntual: Token.Puede ya suma perfil más excepción. Dejé el SP de grupos de trabajo. | J29: Escribir el flujo de recuperación de contraseña con token de un solo uso, aunque todavía no se pueda enviar el correo. | K29: El servidor SMTP no está configurado: HU-004 no se puede probar de punta a punta. | L29: HU-007, HU-016, HU-004 | M29: T-1148, T-1151 a T-1152, T-1154, T-1156, T-1158 a T-1159, T-1164, T-1167 a T-1168, T-1170, T-1173, T-1180, T-1183, T-1185 a T-1186, T-1907 | N29: Blocked | P29: Sí
A30: 7 | B30: 46275 | C30: jueves | D30: Catalina Pescio | E30: Product Owner | F30: Sprint 1 | G30: Semana 2 | H30: S6 | I30: Probé HU-007 y HU-017. El permiso puntual vencido seguía dando acceso hasta el siguiente login; quedó reportado. | J30: Dejar escritos los casos de HU-004 para ejecutarlos cuando haya correo. | K30: HU-004 no se puede ejecutar sin SMTP. | L30: HU-007, HU-017, HU-004 | M30: T-1131, T-1134, T-1144 a T-1145, T-1147, T-1150, T-1160 a T-1161, T-1179, T-1182, T-1187 a T-1188 | N30: Blocked | P30: Sí
A31: 7 | B31: 46275 | C31: jueves | D31: Emilio Fuentes | E31: Scrum Master | F31: Sprint 1 | G31: Semana 2 | H31: S6 | I31: Monté la pantalla de grupos de trabajo con la asignación de integrantes. | J31: Cerrar grupos y ayudar con la pantalla de recuperación de contraseña. | K31: Sigo sin los datos del servidor de correo para configurar Web.config. | L31: HU-016, HU-004 | M31: T-1162, T-1165, T-1169, T-1171 a T-1172, T-1174 a T-1175, T-1178, T-1181, T-1184 | N31: In Progress | P31: Sí | Q31: HU-004 queda BLOQUEADA por SMTP y no cuenta para el compromiso del Sprint. Se registra el impedimento y se sigue con el resto.
A32: 8 | B32: 46276 | C32: viernes | D32: Bryan Chávez | E32: Developer | F32: Sprint 1 | G32: Semana 2 | H32: S6 | I32: Dejé el motor de catálogos ampliables: el valor propio del cliente convive con el valor de sistema y no lo pisa. | J32: Terminar los SP de centros de costo y el endpoint del catálogo consolidado. | K32: Ninguno. | L32: HU-021, HU-013 | M32: T-1189, T-1192, T-1195, T-1197, T-1200, T-1205, T-1208, T-1211, T-1213, T-1215, T-1217 a T-1218 | N32: In Progress | P32: Sí
A33: 8 | B33: 46276 | C33: viernes | D33: Catalina Pescio | E33: Product Owner | F33: Sprint 1 | G33: Semana 2 | H33: S6 | I33: Ejecuté HU-016 y empecé los casos del catálogo ampliable. | J33: Probar que un cliente no vea los valores propios de otro cliente. | K33: Ninguno. | L33: HU-016, HU-021 | M33: T-1163, T-1166, T-1176 a T-1177, T-1191, T-1194, T-1203 a T-1204 | N33: In Progress | P33: Sí
A34: 8 | B34: 46276 | C34: viernes | D34: Emilio Fuentes | E34: Scrum Master | F34: Sprint 1 | G34: Semana 2 | H34: S6 | I34: Terminé grupos de trabajo y armé la pantalla del catálogo ampliable, distinguiendo en la grilla el valor de sistema del propio. | J34: Montar centros de costo y registrar las dos pantallas en Menus. | K34: Ninguno. | L34: HU-016, HU-021, HU-013 | M34: T-1162, T-1165, T-1169, T-1171 a T-1172, T-1174 a T-1175, T-1190, T-1193, T-1196, T-1198 a T-1199, T-1201 a T-1202, T-1206, T-1209, T-1212, T-1214, T-1216 | N34: In Progress | P34: Sí
A35: 9 | B35: 46279 | C35: lunes | D35: Bryan Chávez | E35: Developer | F35: Sprint 1 | G35: Semana 2 | H35: S7 | I35: Cerré centros de costo y el perfil propio con cambio de contraseña. La contraseña antigua se valida en el servidor, no en la pantalla. | J35: Revisar los pull request abiertos y dejar master compilando. | K35: Ninguno. | L35: HU-013, HU-005, HU-020 | M35: T-1205, T-1208, T-1211, T-1213, T-1215, T-1217 a T-1218, T-1221, T-1224, T-1226, T-1228, T-1230 a T-1231, T-1236, T-1240, T-1242 | N35: In Review | O35: #27 | P35: Sí
A36: 9 | B36: 46279 | C36: lunes | D36: Catalina Pescio | E36: Product Owner | F36: Sprint 1 | G36: Semana 2 | H36: S7 | I36: Probé el catálogo ampliable y el cambio de contraseña. Los valores propios no se cruzan entre clientes. | J36: Cerrar la ejecución de las 17 historias y dejar el informe de pruebas del Sprint 1. | K36: Ninguno. | L36: HU-021, HU-005, HU-020 | M36: T-1191, T-1194, T-1203 a T-1204, T-1223, T-1233 a T-1235, T-1238, T-1243 a T-1244 | N36: In Review | P36: Sí
A37: 9 | B37: 46279 | C37: lunes | D37: Emilio Fuentes | E37: Scrum Master | F37: Sprint 1 | G37: Semana 2 | H37: S7 | I37: Terminé la consulta de catálogos del sistema y la pantalla de Mi perfil. | J37: Revisar los PR de Bryan y cerrar el tablero para la revisión del Sprint. | K37: Ninguno. | L37: HU-020, HU-005 | M37: T-1222, T-1225, T-1227, T-1229, T-1232, T-1237, T-1239, T-1241 | N37: In Review | P37: Sí | Q37: Mañana se congela el desarrollo: solo corrección de lo que devuelvan las pruebas y cierre de la Definition of Done.
A38: 10 | B38: 46280 | C38: martes | D38: Bryan Chávez | E38: Developer | F38: Sprint 1 | G38: Semana 2 | H38: S7 | I38: Mergeé los pull request pendientes y dejé master compilando. Corregí lo que devolvieron las pruebas de permisos. | J38: Preparar el modelo de activos para el Sprint 2. | K38: Ninguno. | L38: HU-001, HU-002, HU-003, HU-005, HU-006, HU-007 | M38: T-1001, T-1004, T-1006, T-1008 a T-1010, T-1014, T-1017, T-1041, T-1044, T-1046, T-1049, T-1103, T-1106 a T-1107, T-1148, T-1151 a T-1152, T-1154, T-1156, T-1158 a T-1159, T-1221, T-1224, T-1226, T-1228, T-1230 a T-1231, T-1901, T-1903, T-1905 a T-1906 | N38: Done | O38: #31 | P38: Sí
A39: 10 | B39: 46280 | C39: martes | D39: Catalina Pescio | E39: Product Owner | F39: Sprint 1 | G39: Semana 2 | H39: S7 | I39: Recorrí en navegador las 16 historias terminadas y las acepté una por una contra sus criterios. | J39: Escribir por adelantado los casos de prueba de las historias de activos. | K39: Ninguno. | L39: HU-014, HU-017, HU-020, HU-021 | M39: T-1026, T-1029, T-1038 a T-1040, T-1131, T-1134, T-1144 a T-1145, T-1191, T-1194, T-1203 a T-1204, T-1235, T-1238, T-1243 a T-1244 | N39: Done | P39: Sí
A40: 10 | B40: 46280 | C40: martes | D40: Emilio Fuentes | E40: Scrum Master | F40: Sprint 1 | G40: Semana 2 | H40: S7 | I40: Facilité la revisión del Sprint con la Product Owner y moví a Done lo aceptado. Actualicé el burndown. | J40: Armar el tablero del Sprint 2 con las 22 historias de activos y suscripciones. | K40: Ninguno. | L40: HU-010, HU-011, HU-012, HU-013, HU-015, HU-016 | M40: T-1055, T-1058, T-1060, T-1062, T-1064, T-1072, T-1075, T-1077, T-1079 a T-1080, T-1082 a T-1083, T-1088, T-1091, T-1093, T-1095, T-1097, T-1114, T-1117, T-1121, T-1123, T-1125, T-1162, T-1165, T-1169, T-1171 a T-1172, T-1174 a T-1175, T-1206, T-1209, T-1212, T-1214, T-1216 | N40: Done | P40: Sí | Q40: Sprint 1 cerrado: 16 de 17 historias terminadas. HU-004 queda bloqueada por SMTP y se arrastra. En la retrospectiva se acuerda escribir los casos de prueba antes de programar, no después.
A41: 11 | B41: 46281 | C41: miércoles | D41: Bryan Chávez | E41: Developer | F41: Sprint 2 | G41: Semana 1 | H41: S7 | I41: Corrí los scripts del modelo de activos y dejé los SP de tipos de activo con el código automático por iniciales. | J41: Dejar los SP de modelos de activo y su relación con la marca. | K41: Ninguno. | L41: HU-030, HU-031 | N41: In Progress | P41: Sí
...

Sheet Impedimentos
A1: Registro de impedimentos
A2: Todo impedimento declarado en un Daily se anota aquí el mismo día. El Scrum Master es responsable de su gestión y de su cierre.
A4: N.º | B4: Fecha de detección | C4: Sprint | D4: Detectado por | E4: Descripción del impedimento | F4: Tipo | G4: Historia / Tarea afectada | H4: Responsable de resolver | I4: Acción tomada | J4: Estado | K4: Fecha de resolución | L4: Días abierto
A5: 1 | B5: 46264 | C5: Sprint 1 | D5: Bryan Chávez | E5: El servidor SMTP no está configurado. Web.config apunta a smtp.pendiente-de-configurar.cl, así que HU-004 emite el token de recuperación pero el correo nunca sale. Es lo único que impide cerrar una historia del Sprint 1 por causa ajena al código. | F5: Acceso o infraestructura | G5: HU-004 · Recuperar mi contraseña | H5: Emilio Fuentes | I5: Reprogramado al Sprint 6 en la Sprint Review 1 (15-09-2026): toda la infraestructura y los servicios externos se concentran ahí y los provee Código Creativo (T-6301). HU-004 queda construida y en revisión; el criterio del correo se verifica en el Sprint 6. | J5: En gestión | L5: =IF($B5="","",IF($J5="Resuelto",IF($K5="","",$K5-$B5),TODAY()-$B5))
A6: 2 | B6: 46264 | C6: Sprint 1 | D6: Bryan Chávez | E6: No existe la API de almacenamiento de archivos (Blob). Web.config tiene AlmacenamientoApiUrl = PENDIENTE. Hoy impide declarar un pago —el comprobante es obligatorio— y en el Sprint 2 bloquea las evidencias fotográficas, que son ruta crítica. | F6: Dependencia externa | G6: Sprint 2 · Evidencias y archivos | H6: Bryan Chávez | I6: Reprogramado al Sprint 6 en la Sprint Review 1 (15-09-2026), junto con las evidencias desde terreno (HU-140/141): Código Creativo decide proveedor y levanta el servicio (T-6302). Las pantallas web siguen avisando y escondiendo el formulario mientras tanto. | J6: En gestión | L6: =IF($B6="","",IF($J6="Resuelto",IF($K6="","",$K6-$B6),TODAY()-$B6))
A7: 3 | B7: 46264 | C7: Sprint 1 | D7: Bryan Chávez | E7: El proyecto no está en un repositorio git. Sin historial no hay diff que revisar, así que el criterio 9 de la Definition of Done —revisión de código por otro integrante— no se puede cumplir por definición. También obliga a mover a _RETIRADO/ lo que se da de baja, en vez de borrarlo. | F7: Equipo | G7: Definition of Done · criterio 9 | H7: Emilio Fuentes | I7: Pendiente: crear el repositorio y subir el estado actual. Mientras tanto, lo retirado se conserva en C:\Capstone\_RETIRADO con su motivo. | J7: Abierto | L7: =IF($B7="","",IF($J7="Resuelto",IF($K7="","",$K7-$B7),TODAY()-$B7))
A8: 4 | B8: 46264 | C8: Sprint 1 | D8: Bryan Chávez | E8: No está confirmado que la clave de Google Maps tenga restricción por referrer HTTP. Esa clave es pública por diseño —viaja en el script de la página— y lo único que la protege es la restricción en la consola de Google. Sin ella, quien la copie factura contra nuestra cuenta. | F8: Acceso o infraestructura | G8: HU-011 · Administrar las plantas del cliente | H8: Bryan Chávez | I8: Reprogramado al Sprint 6 en la Sprint Review 1 (15-09-2026): restricción de la clave en la consola de Google Cloud (T-6303). | J8: En gestión | L8: =IF($B8="","",IF($J8="Resuelto",IF($K8="","",$K8-$B8),TODAY()-$B8))
A9: 5 | B9: 46264 | C9: Sprint 1 | D9: Bryan Chávez | E9: Ninguna de las 17 historias se ha recorrido en navegador. No es formalidad: el 30-08, abriendo dos pantallas, aparecieron cuatro fallas que el compilador no detecta (dbo.SPLIT inexistente, contraseñas en texto plano, una FK violada al cambiar de perfil y una tabla ausente). | F9: Equipo | G9: Sprint 1 · las 17 historias | H9: Catalina Pescio | I9: Pendiente: sesión de recorrido con la Product Owner. Es lo que separa "En revisión" de "Terminada". | J9: Abierto | L9: =IF($B9="","",IF($J9="Resuelto",IF($K9="","",$K9-$B9),TODAY()-$B9))
A10: 6 | B10: 46266 | C10: Sprint 3 | D10: Bryan Chávez | E10: HU-076 no puede generar ninguna ocurrencia. Plan_Mantenimiento_Ocurrencia.pmo_plan_mantenimiento_hito es NOT NULL contra Plan_Mantenimiento_Hito, que la crea HU-081 del Sprint 4 y hoy tiene cero filas. Los 21 criterios de las siete historias de programación dicen "entonces se genera la ocurrencia", así que ninguno se puede demostrar de punta a punta. | F10: Alcance o requisito | G10: HU-076 · Generar las ocurrencias de forma automática | H10: Catalina Pescio | I10: Mitigado: el cálculo de fechas —lo difícil— ya está hecho y probado en FNC_PROGRAMACION_FECHAS, y el generador lo reutiliza tal cual. Falta decidir si se adelanta una rebanada de datos del Sprint 4 (unas 6 h de SPs, sin pantallas) o si HU-076 se mueve entera al Sprint 4. | J10: Abierto | L10: =IF($B10="","",IF($J10="Resuelto",IF($K10="","",$K10-$B10),TODAY()-$B10))
A11: 7 | B11: 46266 | C11: Sprint 3 | D11: Bryan Chávez | E11: HU-074 está bloqueada por una historia del Sprint 2. Programacion_Condicion apunta a Activo_Variable, que tiene cero filas y ningún mantenedor: eso es HU-041 "Administrar variables de condición", que sigue en Por hacer. El CRUD de condiciones quedó terminado, pero el combo de la ficha aparece sin opciones. | F11: Dependencia externa | G11: HU-074 · Crear una programación por condición · depende de HU-041 | H11: Catalina Pescio | I11: Se dejó SEL_ACTIVO_VARIABLE mínimo para que la pantalla pueda armarse y avisa "no hay variables definidas todavía" en vez de mostrar un desplegable vacío. Falta decidir si HU-041 se trae al Sprint 3 o si HU-074 se saca. | J11: Abierto | L11: =IF($B11="","",IF($J11="Resuelto",IF($K11="","",$K11-$B11),TODAY()-$B11))
A12: 8 | B12: 46266 | C12: Sprint 3 | D12: Bryan Chávez | E12: Programacion_Medidor.pme_activo_medidor es NOT NULL, así que la regla "cada 500 horas" está obligada a nombrar UN horómetro concreto. El criterio 3 de HU-073 pide lo contrario: un plan sobre cuatro blowers idénticos donde cada equipo dispara con su propio horómetro y sin crear cuatro programaciones. | F12: Técnico | G12: HU-073 · Crear una programación por medidor, criterio 3 | H12: Bryan Chávez | I12: La columna debería ser nullable, con NULL = "el medidor que traiga cada activo del plan", que sale de Plan_Mantenimiento_Activo.pac_activo_medidor. Es un ALTER aditivo, pero cambia el modelo y lo decide el equipo. No se aplicó por cuenta propia. | J12: Abierto | L12: =IF($B12="","",IF($J12="Resuelto",IF($K12="","",$K12-$B12),TODAY()-$B12))
A13: 9 | B13: 46266 | C13: Sprint 3 | D13: Bryan Chávez | E13: No existe tabla de feriados y SIGMA es multipaís. El criterio 2 de HU-075 habla de "excluyo los feriados" como si fuera un calendario nacional. | F13: Alcance o requisito | G13: HU-075 · Definir tolerancias y exclusiones, criterio 2 | H13: Catalina Pescio | I13: Hoy se resuelve cargando cada feriado a mano como exclusión con desplazamiento, que funciona y ya está probado, pero obliga a cargarlos cliente por cliente y año por año. Falta decidir si se modela una tabla de feriados por país. | J13: Abierto | L13: =IF($B13="","",IF($J13="Resuelto",IF($K13="","",$K13-$B13),TODAY()-$B13))
A14: 10 | B14: 46266 | C14: Sprint 3 | D14: Bryan Chávez | E14: La salida de compilación de ASP.NET está versionada en el repositorio: tres carpetas "_program files_git_check" con DLLs y archivos .compiled, en la raíz, en Web/Intranet y en App_Code. Cada compilación las modifica —una verificación de hoy ensució 190 archivos— así que van a chocar en cada merge entre ramas. | F14: Equipo | G14: Definition of Done · repositorio limpio | H14: Emilio Fuentes | I14: Pendiente: sacarlas del control de versiones con git rm --cached y agregarlas al .gitignore. No se metió en el PR del día para no mezclarlo con el arreglo de compilación. | J14: Abierto | L14: =IF($B14="","",IF($J14="Resuelto",IF($K14="","",$K14-$B14),TODAY()-$B14))
A15: 11 | B15: 46266 | C15: Sprint 3 | D15: Bryan Chávez | E15: master quedó sin compilar. Al mergear el PR #35 quedaron cuatro clases definidas dos veces —ActivoModelo, ActivoComponente y sus dos controladores— entre ActivoAlcance.cs y los archivos por entidad. El error visible era CS0101, pero el compilador se detiene en la primera y en realidad eran cuatro. | F15: Técnico | G15: Sprint 3 · rama master | H15: Bryan Chávez | I15: Resuelto: se eliminaron los ActivoAlcance*, que eran subconjunto y además leían una columna ETIQUETA que SEL_ACTIVO_COMPONENTE no devuelve. La única propiedad que solo existía ahí —ActivoComponente.etiqueta, que usa RepuestoCompatibilidad.aspx.cs— se movió calculada al archivo por entidad. Rama fix/clases-duplicadas-activo, compilando en EXITCODE=0. Falta abrir y mergear el PR. | J15: En gestión | L15: =IF($B15="","",IF($J15="Resuelto",IF($K15="","",$K15-$B15),TODAY()-$B15))
A16: 12 | B16: 46031 | C16: Sprint 3 | D16: Catalina Pescio | E16: No había una cuenta deshabilitada en la base para poder ejecutar el tercer criterio de aceptación de HU-001. La prueba quedó sin correr. | F16: Acceso o infraestructura | G16: HU-001 · Iniciar sesión, criterio 3 | H16: Catalina Pescio | I16: Resuelto: se confirmó que Catalina puede crear la cuenta deshabilitada ella misma. Queda ejecutar la prueba. | J16: Resuelto | K16: 46031 | L16: =IF($B16="","",IF($J16="Resuelto",IF($K16="","",$K16-$B16),TODAY()-$B16))
A17: 13 | B17: 46031 | C17: Sprint 3 | D17: Catalina Pescio | E17: Error en la instalación de Swagger en la carpeta de la API, que tomó más tiempo del previsto. Quedó instalado pero todavía no se ha visto funcionando. | F17: Técnico | G17: Pruebas del Sprint 1 · documentación de la API | H17: Catalina Pescio | I17: Pendiente: verificar que Swagger levante y responda antes de cerrar la documentación de los endpoints. | J17: Abierto | L17: =IF($B17="","",IF($J17="Resuelto",IF($K17="","",$K17-$B17),TODAY()-$B17))
A18: 14 | B18: 46031 | C18: Sprint 3 | D18: Bryan Chávez | E18: HU-151, trabajar sin conexión, no se puede asignar todavía: no está definido si se resuelve creando la tabla de sincronización en el servidor o con SQLite en el teléfono. Sus tareas son solo de base de datos, API y móvil; no tiene parte web. | F18: Alcance o requisito | G18: HU-151 · Trabajar sin conexión | H18: Bryan Chávez | I18: Acordado en el Daily: queda SIN ASIGNACIÓN y se retoma cuando se empiece a trabajar la aplicación móvil. Antes hay que analizar la historia entre los tres. | J18: Abierto | L18: =IF($B18="","",IF($J18="Resuelto",IF($K18="","",$K18-$B18),TODAY()-$B18))
A19: 15 | B19: 46031 | C19: Sprint 3 | D19: Emilio Fuentes | E19: Los códigos se podían anotar a mano con cualquier número o letra, así que dos personas nombraban distinto el mismo registro. | F19: Técnico | G19: Módulo de activos e inventario · códigos | H19: Emilio Fuentes | I19: Resuelto: se automatizó la generación del código con las iniciales de cada módulo, y quedó aplicado también en inventario. | J19: Resuelto | K19: 46031 | L19: =IF($B19="","",IF($J19="Resuelto",IF($K19="","",$K19-$B19),TODAY()-$B19))
A20: 16 | B20: 46295 | C20: Sprint 3 | D20: Emilio Fuentes | E20: Emilio declara carga académica de otro ramo durante la semana 1 del Sprint 3. La capacidad real del equipo baja y la parte web se concentra en Bryan. | F20: Equipo | G20: Sprint 3 — módulo de inventario | H20: Emilio Fuentes | I20: Mitigado: Bryan absorbe las historias de programación. Se acuerda revisar el reparto en la planificación del Sprint 4. | J20: Resuelto | K20: 46309 | L20: =IF($B20="","",IF($J20="Resuelto",IF($K20="","",$K20-$B20),TODAY()-$B20))
A21: 17 | B21: 46309 | C21: Sprint 4 | D21: Bryan Chávez | E21: HU-095 depende de HU-094 y las dos son del mismo Sprint. Si la programación del checklist no está publicada, la ejecución en terreno no tiene qué bajar al teléfono. | F21: Dependencia externa | G21: HU-095 — Ejecutar un checklist en terreno | H21: Emilio Fuentes | I21: Acordado en el Daily: Emilio adelanta HU-094 en los primeros días para desbloquear a Bryan. | J21: En gestión | L21: =IF($B21="","",IF($J21="Resuelto",IF($K21="","",$K21-$B21),TODAY()-$B21))
A22: 18 | B22: 46309 | C22: Sprint 4 | D22: Catalina Pescio | E22: Catalina toma por primera vez tareas de API y no conoce el patrón de los controladores ni el middleware que valida la KEY del cliente contra FNC_SUSCRIPCION. | F22: Equipo | G22: HU-140 y HU-141 — tareas de API | H22: Bryan Chávez | I22: Acordado en el Daily: Bryan hace una sesión de traspaso del patrón de la API antes de que Catalina empiece HU-140. | J22: En gestión | L22: =IF($B22="","",IF($J22="Resuelto",IF($K22="","",$K22-$B22),TODAY()-$B22))
A23: 19 | B23: 46322 | C23: Sprint 4 | D23: Bryan Chávez | E23: HU-082 (actividades del hito) y HU-091 (umbrales y acciones del ítem) no están construidas: solo existen sus tablas del modelo inicial (Plan_Mantenimiento_Actividad y Checklist_Item_Validacion), sin SP, sin pantalla y sin fila en Menus. Sin ellas no hay nada que probar ni documentar. | F23: Dependencia interna | G23: HU-082 y HU-091 · T-4064 a T-4066 y T-4135 a T-4137 | H23: Catalina Pescio | I23: Las seis tareas de prueba, documentación y validación quedan Bloqueada en el Sprint Backlog 4. El equipo acuerda que HU-082 y HU-091 son la primera prioridad del Sprint 5 aunque pertenezcan al 4. | J23: Abierto | L23: =IF($B23="","",IF($J23="Resuelto",IF($K23="","",$K23-$B23),TODAY()-$B23))
A24: 20 | B24: 46322 | C24: Sprint 4 | D24: Bryan Chávez | E24: HU-097 (historial de ejecuciones de una pauta) no está construida: la tabla Checklist_Ocurrencia_Historial existe desde el modelo inicial pero no hay SEL_ que la consulte ni pantalla que la muestre. | F24: Dependencia interna | G24: HU-097 · T-4304 y T-4305 | H24: Catalina Pescio | I24: Las dos tareas quedan Bloqueada. Se arrastran al Sprint 5. | J24: Abierto | L24: =IF($B24="","",IF($J24="Resuelto",IF($K24="","",$K24-$B24),TODAY()-$B24))
A25: 21 | B25: 46322 | C25: Sprint 4 | D25: Bryan Chávez | E25: HU-093 y HU-094 viven solo en la base de datos compartida: cinco SP creados directamente contra el servidor el 21-09-2026 (PUBLICAR_CHECKLIST_VERSION y SEL_CHECKLIST_VERSION a las 19:04; SEL, INS y UPD_CHECKLIST_PROGRAMACION a las 20:13). Ninguno está en un bloque de BD/, ni en la rama EmilioFuentes ni en ninguna otra: se revisó la historia completa del repositorio. Las tres páginas que registran las filas 2212, 2213 y 2214 de Menus (ChecklistVersion.aspx, ChecklistProgramacions.aspx, ChecklistProgramacion.aspx) tampoco existen, y «Programación de pautas» está visible para los siete perfiles: hace 404. | F25: Técnico | G25: HU-093 y HU-094 · T-4197 y T-4198 | H25: Emilio Fuentes | I25: Se le pide a Emilio que suba su rama con los cinco scripts y las tres páginas. Mientras tanto T-4197 y T-4198 siguen Bloqueada. Si no alcanza, la alternativa es extraer las definiciones desde la base a un bloque BD/ y ocultar la fila 2213 de Menus. | J25: Abierto | L25: =IF($B25="","",IF($J25="Resuelto",IF($K25="","",$K25-$B25),TODAY()-$B25))
A26: 22 | L26: =IF($B26="","",IF($J26="Resuelto",IF($K26="","",$K26-$B26),TODAY()-$B26))
A27: 23 | L27: =IF($B27="","",IF($J27="Resuelto",IF($K27="","",$K27-$B27),TODAY()-$B27))
A28: 24 | L28: =IF($B28="","",IF($J28="Resuelto",IF($K28="","",$K28-$B28),TODAY()-$B28))
A29: 25 | L29: =IF($B29="","",IF($J29="Resuelto",IF($K29="","",$K29-$B29),TODAY()-$B29))
A30: 26 | L30: =IF($B30="","",IF($J30="Resuelto",IF($K30="","",$K30-$B30),TODAY()-$B30))
A31: 27 | L31: =IF($B31="","",IF($J31="Resuelto",IF($K31="","",$K31-$B31),TODAY()-$B31))
A32: 28 | L32: =IF($B32="","",IF($J32="Resuelto",IF($K32="","",$K32-$B32),TODAY()-$B32))
A33: 29 | L33: =IF($B33="","",IF($J33="Resuelto",IF($K33="","",$K33-$B33),TODAY()-$B33))
A34: 30 | L34: =IF($B34="","",IF($J34="Resuelto",IF($K34="","",$K34-$B34),TODAY()-$B34))
A35: 31 | L35: =IF($B35="","",IF($J35="Resuelto",IF($K35="","",$K35-$B35),TODAY()-$B35))
A36: 32 | L36: =IF($B36="","",IF($J36="Resuelto",IF($K36="","",$K36-$B36),TODAY()-$B36))
A37: 33 | L37: =IF($B37="","",IF($J37="Resuelto",IF($K37="","",$K37-$B37),TODAY()-$B37))
... A64: 60 | L64: =IF($B64="","",IF($J64="Resuelto",IF($K64="","",$K64-$B64),TODAY()-$B64))

Sheet Instructivo y GitHub
A1: Cómo se usa esta bitácora
A3: Reglas de registro
A4: Elemento | B4: Quién lo completa | C4: Regla
A5: Celdas en amarillo con texto azul | B5: Cada integrante | C5: Son las únicas que se editan. El resto del calendario está precargado y no se modifica.
A6: Qué hice desde el último Daily | B6: Cada integrante | C6: Una o dos líneas, en pasado y con hechos verificables. Se nombra la historia o la tarea, no la actividad genérica: «HU-001 terminada, falta la prueba de bloqueo», no «avancé en login».
A7: Qué haré hasta el próximo Daily | B7: Cada integrante | C7: Compromiso concreto para las próximas veinticuatro horas. Si no cabe en un día, la tarea está mal descompuesta y se divide en el Sprint Backlog.
A8: Impedimentos | B8: Cada integrante | C8: Se escribe «Ninguno» cuando no hay. Cuando hay, se describe en una línea y se copia el mismo día a la hoja Impedimentos con su número.
A9: Historia y Tarea | B9: Cada integrante | C9: Identificadores del Sprint Backlog: HU-xxx y T-xxxx. Permiten cruzar la bitácora con el Sprint Backlog y con el tablero.
A10: Estado en GitHub Projects | B10: Cada integrante | C10: Estado de la tarea en el tablero al momento del Daily. Debe coincidir con lo que muestra GitHub; si no coincide, se corrige el tablero, no la bitácora.
A11: Issue / PR | B11: Cada integrante | C11: Número del issue o del pull request asociado, por ejemplo #42. Es el enlace con el repositorio.
A12: Realizado | B12: Scrum Master | C12: «Sí» cuando la persona participó del Daily. «No» cuando no participó; la celda se marca en rojo y baja el indicador de cumplimiento.
A13: Acuerdo del equipo y próximos pasos | B13: Scrum Master | C13: Se escribe una sola vez por Daily, en la fila de cualquier integrante. Recoge la decisión del equipo, no el resumen de lo dicho.
A15: Equivalencia con GitHub Projects
A16: Estado en el Sprint Backlog | B16: Columna en GitHub Projects | C16: Qué significa
A17: Por hacer | B17: Todo | C17: La tarea está en el Sprint y nadie la ha tomado.
A18: En curso | B18: In Progress | C18: Alguien la tomó y la está construyendo. Una persona no debería tener más de una tarea en este estado.
A19: En revisión | B19: In Review | C19: El pull request está abierto y espera la revisión de otro integrante, según el criterio 7 de la Definition of Done.
A20: Terminada | B20: Done | C20: Cumple los diez criterios de la Definition of Done. No se usa para «terminé de programar».
A21: Bloqueada | B21: Blocked | C21: Existe un impedimento registrado que impide avanzar. Toda tarea en este estado tiene una fila en la hoja Impedimentos.
A23: Ejemplo de un registro completo
A24: Columna | B24: Valor de ejemplo | C24: Comentario
A25: Fecha | B25: 03-09-2026 | C25: Precargada. Segundo Daily del Sprint 1.
A26: Integrante | B26: Bryan Chávez | C26: Precargado: hay una fila por integrante y por Daily.
A27: Qué hice desde el último Daily | B27: Terminé el modelo de datos de HU-001 y dejé el endpoint de autenticación respondiendo en el ambiente de demostración. | C27: Hechos, con la historia identificada.
A28: Qué haré hasta el próximo Daily | B28: T-1003: pantalla de inicio de sesión en la web, con el bloqueo por cinco intentos fallidos. | C28: Compromiso para un día, con la tarea identificada.
A29: Impedimentos | B29: Ninguno | C29: Se escribe «Ninguno» cuando no hay.
A30: Historia | B30: HU-001 | C30: Identificador del Product Backlog.
A31: Tarea | B31: T-1003 | C31: Identificador del Sprint Backlog del Sprint 1.
A32: Estado en GitHub Projects | B32: In Progress | C32: Coincide con la columna del tablero.
A33: Issue / PR | B33: #42 | C33: Enlace con el repositorio.
A34: Realizado | B34: Sí | C34: Lo marca el Scrum Master al cerrar el Daily.
A35: Acuerdo del equipo y próximos pasos | B35: Se adelanta la revisión de permisos al jueves para no bloquear HU-006. | C35: Una sola vez por Daily.
A37: El Daily Scrum dura quince minutos y no es una reunión de estado para la jefatura: es la sincronización del equipo. Si una conversación necesita más tiempo, se anota el acuerdo, se cierra el Daily y esa conversación continúa después con quienes corresponda. El registro se completa durante el Daily o inmediatamente después; una bitácora escrita el viernes de memoria no es evidencia, es reconstrucción.
